Workbook

Sheet 개요
A1: 주된 점검인력 | C1: 점검자경력수첩
A2: 보조 점검인력 | C2: 점검자경력수첩 | E2: =E1
A3: 보조 점검인력 | C3: 점검자경력수첩 | E3: =E2
A4: 보조 점검인력 | C4: 점검자경력수첩 | E4: =E3
A5: 보조 점검인력 | C5: 점검자경력수첩 | E5: =E4
A6: 보조 점검인력 | C6: 점검자경력수첩 | E6: =E5
A7: 보조 점검인력 | C7: 점검자경력수첩 | E7: =E6
A8: 보조 점검인력 | C8: 점검자경력수첩 | E8: =E6
A9: 년도 | C9: 위임장 | E9: 이행조치필요기간 | G9: =B10 | H9: ~ | I9: =G9+J9-1 | K9: 일
A10: 발신일자 | C10: 관계인 | D10: =B17 | E10: 이행조치일자 | G10: =I9
A11: 문서번호 | B11: =B10 | C11: 직 위
A12: 점검일자 | C12: 연락처 | D12: =B19
A13: 세대 수 | C13: 생년월일
A14: 상호 | C14: 관할소방서
A15: 대상물 구분(용도) | C15: 건물 동수
A16: 소재지
A17: 소방안전관리자 성명 | C17: 연 면적
A18: 소방안전관리등급 | C18: 건축 면적
A19: 전화번호 | C19: 사용 승인일
A20: 최근 교육이수일 | C20: 건축 허가일
A21: 높이 | C21: 경사로
A22: 지상
A23: 지하

Sheet 보고서
A1: ■ 소방시설 설치 및 관리에 관한 법률 시행규칙 [별지 제9호서식] | F1: (8쪽 중 제1쪽)
A2: [√] 작동점검, 종합점검(［ ］최초점검, ［ ］그 밖의 종합점검) 소방시설등 자체점검 실시결과 보고서
A3: ※ [ ]에는 해당되는 곳에 √ 표기를 합니다.
A4: 특정소방 대 상 물 | B4: 명칭(상호) | C4: =개요!B14 | E4: 대상물 구분(용도)
E5: =개요!B15
B6: 소재지 | C6: =개요!B16
A8: 점검기간 | B8: =개요!E1 | E8: ( 총 점검일수 : | F8: =개요!F1
A9: 점 검 자 | B9: [ ]관계인 (성명: | E9: , 전화번호: )
B10: [ ]소방안전관리자 (성명: | E10: , 전화번호: )
B11: [√]소방시설관리업자 (업체명: | D11: ㈜승진소방이엔지 | E11: , 전화번호: 031-772-3019 )
B12: 전자우편 송달 동의 | C12: 「행정절차법」 제14조에 따라 정보통신망을 이용한 문서 송달에 동의합니다.
C13: [ ] 동의함 [√] 동의하지 않음
D14: 관계인 | E14: =개요!B17 | F14: (서명 또는 인)
C15: 전자우편 주소 @
A16: 점검인력 | B16: 구 분 | C16: 성 명 | D16: 자격구분 | E16: 자격번호 | F16: 점검참여일(기간)
B17: =개요!A1 -> 주된 점검인력 | C17: 김흥준 | D17: 소방시설관리사 | E17: 제2005-60호 | F17: =개요!E1
B18: =개요!A2 -> 보조 점검인력 | C18: =개요!B2 | D18: =개요!C2 -> 점검자경력수첩 | E18: =개요!D2 | F18: =개요!E2
B19: =개요!A3 -> 보조 점검인력 | C19: =개요!B3 | D19: =개요!C3 -> 점검자경력수첩 | E19: =개요!D3 | F19: =개요!E3
B20: =개요!A4 -> 보조 점검인력 | C20: =개요!B4 | D20: =개요!C4 -> 점검자경력수첩 | E20: =개요!D4 | F20: =개요!E4
B21: =개요!A5 -> 보조 점검인력 | C21: =개요!B5 | D21: =개요!C5 -> 점검자경력수첩 | E21: =개요!D5 | F21: =개요!E5
B22: =개요!A6 -> 보조 점검인력 | C22: =개요!B6 | D22: =개요!C6 -> 점검자경력수첩 | E22: =개요!D6 | F22: =개요!E6
B23: =개요!A7 -> 보조 점검인력 | C23: =개요!B7 | D23: =개요!C7 -> 점검자경력수첩 | E23: =개요!D7 | F23: =개요!E7
B24: =개요!A8 -> 보조 점검인력 | C24: =개요!B8 | D24: =개요!C8 -> 점검자경력수첩 | E24: =개요!D8 | F24: =개요!E8
A25: 「소방시설 설치 및 관리에 관한 법률」 제23조제3항 및 같은 법 시행규칙 제23조제1항 및 제2항에 따라 위와 같이 소방시설등 자체점검 실시결과 보고서를 제출합니다.
D26: =개요!B10
A27: 관계인 : | E27: =개요!B17 | F27: (서명 또는 인)
A28: =개요!D14 | B28: 소방서장 귀하
A29: 구 분 | C29: 첨부서류
A30: 소방시설관리업자 또는 소방안전 관리자가 관계인에게 제출 | C30: 소방청장이 정하여 고시하는 소방시설등점검표
A31: 관계인이 소방본부장 또는 소방서장에게 제출 | C31: 1. 점검인력 배치확인서(소방시설관리업자가 점검한 경우에만 제출합니다) 1부 2. 별지 제10호서식의 소방시설등의 자체점검 결과 이행계획서
A32: 유의 사항
A33: 「소방시설 설치 및 관리에 관한 법률」 제58조 제1호 및 제61조 제1항 제8호 | C33: 1. 특정소방대상물의 관계인이 소방시설등에 대한 자체점검을 하지 않거나 관리업자 등으로 하여금 정기적으로 점검하게 하지 않은 경우 1년 이하의 징역 또는 1천만원 이하의 벌금에 처합니다. 2. 특정소방대상물의 관계인이 소방시설등의 점검 결과를 보고하지 않거나 거짓으로 보고한 경우 300만원 이하의 과태료를 부과합니다.

Sheet 정보
J1: (8쪽 중 제2쪽)
A2: 특정소방대상물 정보
A3: ※ [ ]에는 해당되는 곳에 √ 표기를 합니다.
A4: 1. 소방안전정보
A5: 대 표 자 | B5: [ ]소유자, [√]관리자, [ ]점유자
B6: 성명 | C6: =개요!B17 | E6: 전화번호: | G6: =개요!B19
A7: 소방안전 관리등급 | B7: =개요!B18
A8: 소방안전 관 리 자 | B8: [ ]소방기술자격, [√]소방안전관리자수첩, [ ]업무대행감독, [ ]겸직, [ ]기타
B9: 성명 | C9: =개요!B17 | D9: 전화번호 | E9: =개요!B19 | H9: 최근 교육이수일: | J9: =개요!B20
A10: 소방계획서 | B10: [√]작성 ([√]보관 [ ]미보관), [ ]미작성
A11: 자체점검 (전년도) | B11: 작동기능점검 ([√]실시 [ ]미실시), 종합정밀점검 ([ ]실시 [ ]미실시)
A12: 교육훈련 | B12: 소방안전교육 ([√]실시 [ ]미실시), 소방훈련 ([√]실시 [ ]미실시)
A13: 화재보험 | B13: [√]가입, [ ]미가입 보험사: , 가입기간: 2024년 1월 1일 ~ 2024년 12월 31일 가입금액: 대인( 만원 ) 대물( 만원 )
A14: 다중이용 업소현황 | B14: [ ]휴게음식점영업( 개소) [ ]단란주점영업( 개소) [ ]비디오물감상실업 ( 개소) [ ]학원( 개소) [ ]찜질방업( 개소) [ ]복합유통게임제공업 ( 개소) [ ]산후조리업( 개소) [ ]가상체험 체육시설업 ( 개소) [ ]화상대화방업( 개소) [√]해당없음 | E14: [ ]제과점영업( 개소) [ ]유흥주점영업( 개소) [ ]비디오물소극장업 ( 개소) [ ]독서실( 개소) [ ]게임제공업( 개소) [ ]노래연습장업( 개소) [ ]고시원업( 개소) [ ]안마시술소( 개소) [ ]수면방업( 개소) | I14: [ ]일반음식점영업( 개소) [ ]영화상영관( 개소) [ ]복합영상물제공업 ( 개소) [ ]목욕장업( 개소) [ ]인터넷컴퓨터게임시설 제공업( 개소) [ ]권총사격장( 개소) [ ]전화방업( 개소) [ ]콜라텍업( 개소)
A15: 2. 건축물 정보
A16: 건축허가일 | B16: =개요!D20 | F16: 사용승인일 | I16: =개요!D19 개요!D19
A17: 연 면 적 | B17: =개요!D17 | C17: ㎡ | D17: 건축면적 | E17: =개요!D18 | F17: ㎡ | G17: 세대수(세대별점검현황) | J17: =개요!B13 개요!B13 | K17: 세대
A18: 층 수 | B18: 지상 | C18: =개요!B22 | D18: 지하 | E18: =개요!B23 | F18: 높 이 | H18: =개요!B21 | I18: m | J18: 건물동수 | K18: =개요!D15
A19: 건축물구조 | B19: [√]철근콘크리트구조, [ ]철골구조, [ ]조적조, [ ]목구조, [ ]기타
A20: 지붕구조 | B20: [ ]슬라브, [ ]기와, [ ]슬레이트, [√]기타 | I20: 경사로 | J20: =개요!D21 | K20: 개소
A21: 계 단 | B21: [√]직통(또는 피난계단) ( 1 개소 ), [ ]특별피난계단 ( 개소)
A22: 승 강 기 | B22: [ ]승용( 대 ), [ ]비상용( 대), [ ]피난용( 대)
A23: 주 차 장 | B23: [ ]옥내([ ]지하 [ ]지상 [ ]필로티 [ ]기계식), [ ]옥상, [√]옥외

Sheet 다수동일때
J1: (8쪽 중 제2쪽)
A2: 2. 건축물 정보
A3: 건축허가일 | F3: 사용승인일
A4: 연 면 적 | C4: ㎡ | D4: 건축면적 | F4: ㎡ | G4: 세대수(세대별점검현황) | K4: 세대
A5: 층 수 | B5: 지상 | D5: 지하 | F5: 높 이 | I5: m | J5: 건물동수
A6: 건축물구조 | B6: [√]콘크리트구조, [ ]철골구조, [ ]조적조, [ ]목구조, [ ]기타
A7: 지붕구조 | B7: [ ]슬라브, [ ]기와, [ ]슬레이트, [√]기타 | I7: 경사로 | K7: 개
A8: 계 단 | B8: [√]직통(또는 피난계단) ( 1 개소 ), [ ]특별피난계단 ( 개소)
A9: 승 강 기 | B9: [ ]승용( 대 ), [ ]비상용( 대), [ ]피난용( 대)
A10: 주 차 장 | B10: [ ]옥내([ ]지하 [ ]지상 [ ]필로티 [ ]기계식), [ ]옥상, [√]옥외
A12: 2. 건축물 정보
A13: 건축허가일 | F13: 사용승인일
A14: 연 면 적 | C14: ㎡ | D14: 건축면적 | F14: ㎡ | G14: 세대수(세대별점검현황) | K14: 세대
A15: 층 수 | B15: 지상 | D15: 지하 | F15: 높 이 | I15: m | J15: 건물동수
A16: 건축물구조 | B16: [√]콘크리트구조, [ ]철골구조, [ ]조적조, [ ]목구조, [ ]기타
A17: 지붕구조 | B17: [ ]슬라브, [ ]기와, [ ]슬레이트, [√]기타 | I17: 경사로 | K17: 개
A18: 계 단 | B18: [√]직통(또는 피난계단) ( 1 개소 ), [ ]특별피난계단 ( 개소)
A19: 승 강 기 | B19: [ ]승용( 대 ), [ ]비상용( 대), [ ]피난용( 대)
A20: 주 차 장 | B20: [ ]옥내([ ]지하 [ ]지상 [ ]필로티 [ ]기계식), [ ]옥상, [√]옥외
A22: 2. 건축물 정보
A23: 건축허가일 | F23: 사용승인일
A24: 연 면 적 | C24: ㎡ | D24: 건축면적 | F24: ㎡ | G24: 세대수(세대별점검현황) | K24: 세대
A25: 층 수 | B25: 지상 | D25: 지하 | F25: 높 이 | I25: m | J25: 건물동수
A26: 건축물구조 | B26: [√]콘크리트구조, [ ]철골구조, [ ]조적조, [ ]목구조, [ ]기타
A27: 지붕구조 | B27: [ ]슬라브, [ ]기와, [ ]슬레이트, [√]기타 | I27: 경사로 | K27: 개
A28: 계 단 | B28: [√]직통(또는 피난계단) ( 1 개소 ), [ ]특별피난계단 ( 개소)
A29: 승 강 기 | B29: [ ]승용( 대 ), [ ]비상용( 대), [ ]피난용( 대)
A30: 주 차 장 | B30: [ ]옥내([ ]지하 [ ]지상 [ ]필로티 [ ]기계식), [ ]옥상, [√]옥외

Sheet 현황
AM1: (8쪽 중 제3쪽)
A2: 소방시설등의 현황
A3: ※ [ ]에는 해당 시설에 √ 표를 하고, 점검결과란은 양호○. 불량×. 해당없는 항목은 /표시를 합니다. (1면)
A4: 1. 소방시설등 점검결과
A5: 구분 | C5: 해 당 설 비 | S5: 점검결과 | W5: 구분 | Y5: 해 당 설 비 | AO5: 점검결과
A6: 소화 설비 | C6: [ ] | E6: 소화기구 및 자동소화장치 | W6: 피난 구조 설비 | Y6: [ ] | AA6: 피난기구
D7: [ ] | F7: 소화기구(소화기,자확,간이) | S7: ="" | Z7: [ ] | AB7: 공기안전매트·피난사다리 | AO7: =""
D8: [ ] | F8: 주거용주방자동소화장치 | S8: ="" | AB8: (간이)완강기·미끄럼대·구조대
D9: [ ] | F9: 상업용주방자동소화장치 | S9: ="" | Z9: [ ] | AB9: 다수인피난장비 | AO9: =""
D10: [ ] | F10: 캐비닛형자동소화장치 | S10: ="" | Z10: [ ] | AB10: 승강식피난기 | AO10: =""
D11: [ ] | F11: 가스·분말·고체자동소화장치 | S11: ="" | AB11: 하향식피난구용내림식사다리
C12: [ ] | E12: 옥내소화전설비 | S12: ="" | Y12: [ ] | AA12: 인명구조기구 | AO12: =""
C13: [ ] | E13: 스프링클러설비 | S13: ="" | Y13: [ ] | AA13: 유도등 | AO13: =""
C14: [ ] | E14: 간이스프링클러설비 | S14: ="" | Y14: [ ] | AA14: 유도표지 | AO14: =""
C15: [ ] | E15: 화재조기진압용스프링클러설비 | S15: ="" | Y15: [ ] | AA15: 피난유도선 | AO15: =""
C16: [ ] | E16: 물분무소화설비 | S16: ="" | Y16: [ ] | AA16: 비상조명등 | AO16: =""
C17: [ ] | E17: 미분무소화설비 | S17: ="" | Y17: [ ] | AA17: 휴대용비상조명등 | AO17: =""
C18: [ ] | E18: 포소화설비 | S18: ="" | W18: 소화 용수 설비 | Y18: [ ] | AA18: 상수도소화용수설비 | AO18: =""
C19: [ ] | E19: 이산화탄소소화설비 | S19: ="" | Y19: [ ] | AA19: 소화수조 및 저수조 | AO19: =""
C20: [ ] | E20: 할론소화설비 | S20: ="" | W20: 소화 활동 설비 | Y20: [ ] | AA20: 거실제연설비 | AO20: =""
C21: [ ] | E21: 할로겐화합물 및 불활성기체 소화설비 | S21: ="" | Y21: [ ] | AA21: 부속실 등 제연설비 | AO21: =""
C22: [ ] | E22: 분말소화설비 | S22: ="" | Y22: [ ] | AA22: 연결송수관설비 | AO22: =""
C23: [ ] | E23: 강화액소화설비 | S23: ="" | Y23: [ ] | AA23: 연결살수설비 | AO23: =""
C24: [ ] | E24: 고체에어로졸소화설비 | S24: ="" | Y24: [ ] | AA24: 비상콘센트설비 | AO24: =""
C25: [ ] | E25: 옥외소화전설비 | S25: ="" | Y25: [ ] | AA25: 무선통신보조설비 | AO25: =""
A26: 경보 설비 | C26: [ ] | E26: 단독경보형감지기 | S26: ="" | Y26: [ ] | AA26: 연소방지설비 | AO26: =""
C27: [ ] | E27: 비상경보설비 | S27: ="" | W27: 기타 | Y27: [ ] | AA27: 방화문, 방화셔터 | AO27: =""
C28: [ ] | E28: 자동화재탐지설비 및 시각경보기 | S28: ="" | Y28: [ ] | AA28: 비상구, 피난통로 | AO28: =""
C29: [ ] | E29: 비상방송설비 | S29: ="" | Y29: [ ] | AA29: 방 염 | AO29: =""
C30: [ ] | E30: 통합감시시설 | S30: ="" | W30: 비고
C31: [ ] | E31: 자동화재속보설비 | S31: =""
C32: [ ] | E32: 누전경보기 | S32: =""
C33: [ ] | E33: 가스누설경보기 | S33: =""
A35: 2.안전시설등 점검결과 (다중이용업소)
A36: 구분 | C36: 해 당 설 비 | S36: 점검결과 | W36: 구분 | Y36: 해 당 설 비 | AO36: 점검결과
A37: 소화 설비 | C37: [ ] | E37: 소화기 또는 자동확산소화기 | S37: ="" | W37: 비상구 | Y37: [ ] | AA37: 방화문 | AO37: =""
C38: [ ] | E38: 간이스프링클러설비 | S38: ="" | Y38: [ ] | AA38: 비상구(비상탈출구) | AO38: =""
A39: 경보 설비 | C39: [ ] | E39: 비상경보설비 또는 자동화재탐지설비 | S39: ="" | W39: 기타 | Y39: [ ] | AA39: 영업장 내부 피난통로 | AO39: =""
C40: [ ] | E40: 가스누설경보기 | S40: ="" | Y40: [ ] | AA40: 영상음향차단장치 | AO40: =""
A41: 피난 구조 설비 | C41: [ ] | E41: 피난기구 | S41: ="" | Y41: [ ] | AA41: 누전차단기 | AO41: =""
...

Sheet 현1
S1: (8쪽 중 제4쪽)
A2: 3. 소방시설등의 세부현황 3-1. 소화기구, 자동소화장치
A3: 구분 | C3: =현황!D7 -> [ ] | D3: 소화기 | J3: [ ] | K3: 간이소화용구 | O3: [ ] | P3: 자동 | R3: [ ] | S3: 자동 | T3: 비 고
B4: [ ] | C4: 분말 | G4: [ ] | H4: 기타 | I4: [ ] | J4: 투척용 | L4: [ ] | M4: 기타 | N4: 확산소화기 | Q4: 소화장치
A5: 합계 | B5: =SUM(B7:F14) -> 0 | G5: =SUM(G7:H14) -> 0 | I5: =SUM(I7:K14) -> 0 | L5: =SUM(L7:M14) -> 0 | N5: =SUM(N7:P14) -> 0 | Q5: =SUM(Q7:S14) -> 0
A6: 동명
A7: 1
A8: 2
A9: 3
A10: 4
A11: 5
A12: 6
A13: 7
A14: 8
A15: 3-2. 수계소화설비(공통사항)
A16: 수원 | B16: 주된수원 | G16: ◦ 설비의 종류: [ ]옥내소화전설비 [ ]옥외소화전설비 [ ]스프링클러설비
G17: [ ]간이스프링클러설비 [ ]화재조기진압용스프링클러설비
G18: [ ]물분무소화설비 [ ]미분무소화설비 [ ]포소화설비
G19: ◦ 설치장소: 동명( ) [ ]지상/[ ]지하 ( )층, 실명( )
G20: ◦ 흡입방식: [ ]정압 [ ]부압, ◦ 유효수량: ( )㎥
B21: 보조수원 | G21: ◦ 설치장소: 동명( ) 실명( ), ◦ 유효수량: ( )㎥
A22: 가압 송수 장치 | B22: [ ]고가수조 | G22: ◦ 설비의 종류: [ ]옥내소화전설비 [ ]옥외소화전설비 [ ]스프링클러설비
G23: [ ]간이스프링클러설비 [ ]화재조기진압용스프링클러설비
G24: [ ]물분무소화설비 [ ]미분무소화설비 [ ]포소화설비
G25: ◦ 설치장소: 동명( ) 실명( ), ◦ 유효수량: ( )㎥
B26: [ ]압력수조 | G26: ◦ 설비의 종류: [ ]옥내소화전설비 [ ]옥외소화전설비 [ ]스프링클러설비
G27: [ ]간이스프링클러설비 [ ]화재조기진압용스프링클러설비
G28: [ ]물분무소화설비 [ ]미분무소화설비 [ ]포소화설비
G29: ◦ 설치장소: 동명( ) [ ]지상/[ ]지하 ( )층, 실명( )
G30: ◦ 수조용량: ( )ℓ, 수조가압압력:( )Mpa
G31: ◦ 자동식공기압축기 용량:( )㎥/min, 동 력:( )Kw
B32: [ ]가압수조 | G32: ◦ 설비의 종류: [ ]옥내소화전설비 [ ]옥외소화전설비 [ ]스프링클러설비
G33: [ ]간이스프링클러설비 [ ]화재조기진압용스프링클러설비
G34: [ ]물분무소화설비 [ ]미분무소화설비 [ ]포소화설비
G35: ◦ 설치장소: 동명( ) [ ]지상/[ ]지하 ( )층, 실명( )
G36: ◦ 수조용량: ( )ℓ, 수조가압압력:( )Mpa
G37: ◦ 가압가스의 종류: [ ]공기 [ ]불연성가스( )
A38: 비 고 1. 해당 특정소방대상물에 설치된 소방시설에 대하여만 작성이 가능합니다. 2. [ ]에는 해당 시설에 √ 표를 하고, 세부 현황 및 설치된 수량을 기입합니다. 3. 기입란이 부족한 경우 서식을 추가하여 작성할 수 있습니다.

Sheet 다수동
O1: (8쪽 중 제4쪽)
A2: 3. 소방시설등의 세부현황 3-1. 소화기구, 자동소화장치, 옥내소화전, 스프링클러설비
A3: 구분 | C3: [ ] | D3: 소화기 | G3: [ ] | I3: 간이소화용구 | L3: [ ] | M3: 자동 | N3: [ ] | O3: 자동 | P3: [ ] | Q3: 옥내 | S3: [ ] | T3: 스프링클러
B4: [ ] | C4: 분말 | E4: [ ] | F4: 기타 | G4: [ ] | H4: 투척용 | J4: [ ] | K4: 기타 | L4: 확산소화기 | N4: 소화장치 | P4: 소화전 | R4: [ ] | S4: 습식 | T4: [ ] | U4: 준비작동식
A5: 합계 | B5: =SUM(B7:D31) -> 0 | E5: =SUM(E7:F31) -> 0 | G5: =SUM(G7:I31) -> 0 | J5: =SUM(J7:K31) -> 0 | L5: =SUM(L7:M31) -> 0 | N5: =SUM(N7:O31) -> 0 | P5: =SUM(P7:Q31) -> 0 | R5: =SUM(R7:S31) -> 0 | T5: =SUM(T7:W31) -> 0
A6: 동명

Sheet 현2
H1: (8쪽 중 제5쪽)
A2: 가압 송수 장치 | C2: [ ]펌프방식 | D2: =현1!G16 -> ◦ 설비의 종류: [ ]옥내소화전설비 [ ]옥외소화전설비 [ ]스프링클러설비
D3: =현1!G17 -> [ ]간이스프링클러설비 [ ]화재조기진압용스프링클러설비
D4: =현1!G18 -> [ ]물분무소화설비 [ ]미분무소화설비 [ ]포소화설비
D5: =현1!G19 -> ◦ 설치장소: 동명( ) [ ]지상/[ ]지하 ( )층, 실명( )
D6: ◦ 주펌프 전양정:( )m, 토출량:( )ℓ/min
D7: [ ]전동기 [ ]내연기관(연료:[ ]경유 [ ]기타
D8: ◦ 예비펌프 전양정:( )m, 토출량:( )ℓ/min
D9: [ ]전동기 [ ]내연기관(연료:[ ]경유 [ ]기타
D10: ◦ 충압펌프 전양정:( )m, 토출량:( )ℓ/min
D11: ◦ [ ]물올림장치(유효수량: ( )ℓ, 급수배관: ( )㎜
D12: ◦ 기동장치: [ ]기동용수압개폐장치, [ ]ON/OFF 방식
D13: [ ]압력챔버(용량:( )ℓ, 사용압력:( )MPa)
D14: [ ]기동용압력스위치([ ]부르동관식 [ ]전자식 [ ]그 밖의 것)
D15: ◦ [ ]감압장치 [ ]지상/[ ]지하 ( )층, 설치장소:( )
A16: 송수구 | C16: =D2 -> ◦ 설비의 종류: [ ]옥내소화전설비 [ ]옥외소화전설비 [ ]스프링클러설비
C17: =D3 -> [ ]간이스프링클러설비 [ ]화재조기진압용스프링클러설비
C18: =D4 -> [ ]물분무소화설비 [ ]미분무소화설비 [ ]포소화설비
C19: ◦ 설치장소:( ), [ ]쌍구형 ( )개/[ ]단구형 ( )개
A20: 비상전원 | C20: [ ]자가발전설비([ ]소방전용 [ ]소방부하겸용 [ ]소방전원보존형 [ ]기타( ))
C21: [ ]비상전원수전설비 [ ]축전지설비 [ ]전기저장장치
C22: ◦ 설치장소: 동명( ) [ ]지상/[ ]지하 ( )층, 실명( )
A23: 3-3. 수계소화설비(개별사항)
A24: =현황!C12 -> [ ] | B24: 옥내소화전 | C24: ◦ 설치장소: 동명( ) [ ]전체층/[ ]일부층 [ ]지상/[ ]지하( )층 ~ [ ]지상/[ ]지하( )층
C25: 동명( ) [ ]전체층/[ ]일부층 [ ]지상/[ ]지하( )층 ~ [ ]지상/[ ]지하( )층
C26: ◦ 설치개수가 가장 많은 층의 설치개수: ( )개
A27: =현황!C25 -> [ ] | B27: 옥외소화전 | C27: ◦ 설치개수: ( )개
A28: =현황!C13 -> [ ] | B28: 스프링클러설비 | C28: ◦ 종류: [ ]습식 [ ]부압식 [ ]준비작동식 [ ]건식 [ ]일제살수식
C29: ◦ 설치장소: 동명( ) [ ]전체층/[ ]일부층 [ ]지상/[ ]지하( )층 ~ [ ]지상/[ ]지하( )층
A30: =현황!C14 -> [ ] | B30: 간이 스프링클러설비 | C30: ◦ 종류: [ ]펌프 [ ]캐비닛 [ ]상수도
C31: ◦ 설치장소: 동명( ) [ ]전체층/[ ]일부층 [ ]지상/[ ]지하( )층 ~ [ ]지상/[ ]지하( )층
A32: =현황!C15 -> [ ] | B32: 화재 조기진압용 | C32: ◦ 설치장소: 동명( ) [ ]전체층/[ ]일부층 [ ]지상/[ ]지하( )층 ~ [ ]지상/[ ]지하( )층
C33: 동명( ) [ ]전체층/[ ]일부층 [ ]지상/[ ]지하( )층 ~ [ ]지상/[ ]지하( )층
A34: =현황!C16 -> [ ] | B34: 물분무 소화설비 | C34: ◦ 설치장소: 동명( ) [ ]전체층/[ ]일부층 [ ]지상/[ ]지하( )층 ~ [ ]지상/[ ]지하( )층
C35: 동명( ) [ ]전체층/[ ]일부층 [ ]지상/[ ]지하( )층 ~ [ ]지상/[ ]지하( )층
A36: =현황!C18 -> [ ] | B36: 포 소화설비 | C36: [ ]포워터스프링클러설비 [ ]포헤드설비 [ ]고정포방출설비 [ ]기타( )
C37: ◦ 소화약제 [ ]단백포 [ ]합성계면활성제포 [ ]수성막포 [ ]내알코올포
C38: ◦ 설치장소: 동명( ) [ ]전체층/[ ]일부층 [ ]지상/[ ]지하( )층 ~ [ ]지상/[ ]지하( )층
A39: 3-4. 가스계소화설비(개별사항)
A40: =현황!C19 -> [ ] | B40: 이산화탄소 | C40: [ ]전역방출 [ ]국소방출 [ ]호스릴 / [ ]고압식 [ ]저압식 / [ ]축압식 [ ]가압식
...

Sheet 현3
H1: (8쪽 중 제6쪽)
A2: 3-5. 경보설비
A3: =현황!C26 -> [ ] | B3: 단독 경보형감지기 | C3: ◦ 설치장소: 동명( ) [ ]전체층/[ ]일부층 [ ]지상/[ ]지하( )층 ~ [ ]지상/[ ]지하( )층
C4: ◦ 주전원 [ ]상용전원 [ ]건전지
A5: =현황!C27 -> [ ] | B5: 비상경보설비 | C5: [ ]비상벨설비 [ ]자동식사이렌설비
C6: ◦ 설치장소: 동명( ) [ ]전체층/[ ]일부층 [ ]지상/[ ]지하( )층 ~ [ ]지상/[ ]지하( )층
C7: ◦ 조작장치 설치장소: 동명( ) [ ]지상/[ ]지하 ( )층 실명( )
A8: =현황!C28 -> [ ] | B8: 자동화재 탐지설비 | C8: ◦ 수신기 위치: 동명( ) [ ]지상/[ ]지하 ( )층 실명( )
C9: ◦ 경보방식 [ ]전층경보 [ ]우선경보, 시각경보기 [ ]유 [ ]무
C10: ◦ 설치장소: 동명( ) [ ]전체층/[ ]일부층 [ ]지상/[ ]지하( )층 ~ [ ]지상/[ ]지하( )층
C11: 동명( ) [ ]전체층/[ ]일부층 [ ]지상/[ ]지하( )층 ~ [ ]지상/[ ]지하( )층
C12: ◦ 감지기종류 [ ]열 [ ]연기 [ ]그 밖의 것([ ]불꽃 [ ]아날로그식 [ ]복합형)
A13: =현황!C29 -> [ ] | B13: 비상방송설비 | C13: [ ]전용 [ ]겸용 / [ ]전층경보 [ ]우선경보
C14: ◦ 증폭기 설치장소: 동명( ) [ ]지상/[ ]지하 ( )층, 실명( )
A15: =현황!C31 -> [ ] | B15: 자동화재 속보설비 | C15: ◦ 속보기 설치장소: 동명( ) [ ]지상/[ ]지하 ( )층, 실명( )
A16: =현황!C30 -> [ ] | B16: 통합감시시설 | C16: ◦ 주수신기 설치장소: 동명( ) [ ]지상/[ ]지하 ( )층, 실명( )
C17: ◦ 부수신기 설치장소: 동명( ) [ ]지상/[ ]지하 ( )층, 실명( )
C18: ◦ 정보통신망 [ ]광케이블 [ ]기타( ) / 예비선로 [ ]유 [ ]무
A19: =현황!C32 -> [ ] | B19: 누전경보기 | C19: ◦ 주수신기 설치장소: 동명( ) [ ]지상/[ ]지하 ( )층, 실명( )
C20: ◦ 수신기 형식 [ ]1급 [ ]2급, 차단기구 [ ]무 [ ]유(설치장소: )
A21: =현황!C33 -> [ ] | B21: 가스누설 경보기 | C21: ◦ [ ]단독형 [ ]분리형, 사용가스종류 [ ]LNG [ ]LPG, 경계구역 수: ( )개
C22: ◦ 수신기 설치장소: 동명( ) [ ]지상/[ ]지하 ( )층, 실명( )
C23: ◦ 차단기구 [ ]무 [ ]유(설치장소: )
A24: 3-6. 피난구조설비
A25: =현황!Y6 -> [ ] | B25: 피난기구 | C25: ◦ 종류: [ ]피난사다리 [ ]완강기 [ ]다수인피난장비 [ ]승강식피난기 [ ]미끄럼대
C26: [ ]피난교 [ ]피난용트랩 [ ]구조대 [ ]간이완강기 [ ]공기안전매트
C27: ◦ 설치장소: 동명( ) [ ]전체층/[ ]일부층 [ ]지상/[ ]지하( )층 ~ [ ]지상/[ ]지하( )층
C28: 동명( ) [ ]전체층/[ ]일부층 [ ]지상/[ ]지하( )층 ~ [ ]지상/[ ]지하( )층
A29: =현황!Y12 -> [ ] | B29: 인명 구조기구 | C29: ◦ 종류: [ ]방열복/ 방화복 [ ]공기호흡기 [ ]인공소생기
C30: ◦ 설치장소: 동명( ) [ ]전체층/[ ]일부층 [ ]지상/[ ]지하( )층 ~ [ ]지상/[ ]지하( )층
C31: 동명( ) [ ]전체층/[ ]일부층 [ ]지상/[ ]지하( )층 ~ [ ]지상/[ ]지하( )층
C32: ◦ 대상물의 용도: [ ] 5층이상 병원 [ ] 7층이상 관광호텔 [ ] 이산화탄소소화설비 설치
C33: [ ] 지하역사·백화점·대형점포·쇼핑센타·지하상가·영화상영관
A34: =현황!Y13 -> [ ] | B34: 유도등 | C34: ◦ 종류: [ ]피난구 [ ]통로 [ ]객석유도등 [ ]유도표지 [ ]피난유도선
C35: ◦ 설치장소: 동명( ) [ ]전체층/[ ]일부층 [ ]지상/[ ]지하( )층 ~ [ ]지상/[ ]지하( )층
A36: =현황!Y16 -> [ ] | B36: 비상조명등 | C36: ◦ 설치장소: 동명( ) [ ]전체층/[ ]일부층 [ ]지상/[ ]지하( )층 ~ [ ]지상/[ ]지하( )층
C37: ◦ 비상전원 [ ]자가발전설비 [ ]축전지설비 [ ]내장형
A38: =현황!Y17 -> [ ] | B38: 휴대용 비상조명등 | C38: ◦ 설치장소: 동명( ) [ ]전체층/[ ]일부층 [ ]지상/[ ]지하( )층 ~ [ ]지상/[ ]지하( )층
C39: ◦ 전원 [ ]건전지식 [ ]충전식 배터리식
A40: 3-7. 소화용수설비
...

Sheet 현4
C1: (8쪽 중 제7쪽)
A2: 3-8. 소화활동설비
A3: [ ] | B3: 제 연 설 비 | C3: =현황!Y20 -> [ ] | D3: 거 실 | E3: ◦ 설치장소: 동명( ) [ ]전체층/[ ]일부층 [ ]지상/[ ]지하( )층 ~ [ ]지상/[ ]지하( )층
E4: ◦ 방식 [ ]단독 [ ]공동 [ ]상호 [ ]기타( )
E5: ◦ 기동장치 [ ]자동(감지기 연동) [ ]수동 [ ]원격
E6: ◦ 제연구획면적 최대: ( )㎡ / 구조 [ ]내화 [ ]불연 [ ]그 밖의 것:( )
E7: ◦ 제연구역 출입문 [ ]상시폐쇄(자동폐쇄장치) [ ]상시개방(감지기에 의한 닫힘)
E8: ◦ 급기용송풍기 설치장소: 동명( ) [ ]지상/[ ]지하 ( )층, 실명( )
E9: 전동기 ( )㎾, 풍량 ( )㎥/min, 정압 ( )㎜Aq
E10: ◦ 배출용송풍기 설치장소: 동명( ) [ ]지상/[ ]지하 ( )층, 실명( )
E11: 전동기 ( )㎾, 풍량 ( )㎥/min, 정압 ( )㎜Aq
E12: ◦ 배출구 [ ]천장면 [ ]천장직하 [ ]기타( ) / 옥외배출구 [ ]옥상 [ ]기타( )
E13: 풍도구조 [ ]내화 [ ]불연 [ ]그 밖의 것( ) / 구획댐퍼 [ ]유 [ ]무
E14: ◦ 유입공기배출 [ ]자연배출 [ ]기계배출 [ ]배출구 [ ]제연설비
E15: ◦ 급기구 [ ]강제유입 [ ]자연유입 [ ]인접구역유입
E16: 풍도구조 [ ]내화 [ ]불연 [ ]그 밖의 것( ) / 구획댐퍼 [ ]유 [ ]무
C17: =현황!Y21 -> [ ] | D17: 전 실 | E17: ◦ 설치장소: 동명( , , , , )
E18: 특별피난계단 ( )개소, 비상용승강기 ( )대
E19: ◦ 방식 [ ]부속실 [ ]계단실 및 부속실 [ ] 계단실 [ ] 비상용승강기승강장
E20: ◦ 기동방식 [ ]전층 [ ]부분층( 개층) / 댐퍼개방감지기 [ ]전용 [ ]겸용
E21: ◦ 급기용송풍기 설치장소: 동명( ) [ ]지상/[ ]지하 ( )층, 실명( )
E22: 전동기 ( )㎾, 풍량 ( )㎥/min, 정압 ( )㎜Aq
E23: ◦ 배출용송풍기 설치장소: 동명( ) [ ]지상/[ ]지하 ( )층, 실명( )
E24: 전동기 ( )㎾, 풍량 ( )㎥/min, 정압 ( )㎜Aq
E25: ◦ 제연구역 출입문 [ ]상시폐쇄(자동폐쇄장치) [ ]상시개방(연기감지기에 의한 닫힘)
E26: ◦ 유입공기배출 [ ]자연배출 [ ]기계배출 [ ]배출구 [ ]제연설비
E27: ◦ 과압방지장치 [ ]플랩댐퍼 [ ]자동차압(과압조절형)댐퍼 [ ]그 밖의 것 [ ]해당없음
A28: =현황!Y22 -> [ ] | B28: 연결송수관 | E28: [ ]전용 [ ]겸용([ ]옥내소화전설비 [ ]스프링클러설비 [ ]기타: )
E29: ◦ 설치장소: 동명( ) [ ]전체층/[ ]일부층 [ ]지상/[ ]지하( )층 ~ [ ]지상/[ ]지하( )층
E30: ◦ 방수구 위치 [ ]복도·통로 [ ]계단실 [ ] 계단등의 부근
E31: ◦ 송수구 설치장소:( ), 중간수조용량: ( )㎥
E32: ◦ 가압송수장치 설치장소: 동명( ) [ ]지상/[ ]지하 ( )층, 실명( )
E33: 전양정:( )m, 토출량:( )ℓ/min
E34: [ ]전동기 [ ]내연기관(연료:[ ]경유 [ ]기타)
E35: ◦ 기동스위치 설치장소 [ ]송수구 [ ]방재실 [ ]기타( )
A36: =현황!Y23 -> [ ] | B36: 연결살수 | E36: ◦ 설치장소: 동명( , , , , )
E37: ◦ 방식 [ ]습식 [ ]건식 / [ ]지하층 [ ]판매시설 [ ]가스시설 [ ]부속된 연결통로
E38: ◦ 송수구 설치장소:( ), 송수구역수: ( )구역
A39: =현황!Y24 -> [ ] | B39: 비상콘센트 | E39: ◦ 설치장소: 동명( ) [ ]지상/[ ]지하( )층 ~ [ ]지상/[ ]지하( )층
E40: [ ]3상 380V [ ]단상 220V / [ ]접지형 2극 플러그접속기 [ ]접지형 3극 플러그접속기
...

Sheet 현5
A1: (8쪽 중 제8쪽)
A2: 4. 소방시설등 불량 세부 사항
A3: 설비명 | B3: 점검번호 | C3: 불량내용
A4: 소화설비 | C4: =""
A5: 경보설비 | C5: =""
A6: 피난구조설비 | C6: =""
A7: 소화용수설비 | C7: =""
A8: 소화활동설비 | C8: =""
A9: 기타 | C9: =""
A10: 안전시설등 | C10: =""
A11: 비고 | B11: 점검번호는 소방시설등 자체점검표의 점검항목별 번호를 기입합니다.

Sheet 대상처
F5: =개요!B9
B7: 소방시설 종합점검 결과보고서
B10: =개요!B14
B29: =개요!B10
G35: ㈜ 승 진 소 방 E N G
G36: 경기도 양평군 양평읍 잿말길10번길50-1 (덕평리98-1)
G37: T E L. 0 3 1 - 7 7 2 - 3 0 1 9 F A X. 0 3 1 - 7 7 2 - 2 4 1 9
G38: 소방시설점검 / 소방안전관리 업무대행 / 소방공사

Sheet 공문
A1: 주식회사 승진소방 ENG
A2: 경기도 양평군 양평읍 잿말길10번길 50-1 / Tel) 031-772-3019 / Fax) 031-772-2419
A6: 문서번호 : | B6: 승 진 | C6: =개요!B11 | D6: 선결 | G6: 지시
A7: 발신일자 : | B7: =개요!B10
A8: 수 신 : | B8: =개요!B14 | D8: 접수 | E8: 일자 시간 | G8: 결재
A9: 참 조 : | B9: 소방안전관리자 및 관계인
A10: 발 신 : | B10: ㈜승진소방 ENG | E10: 번호
G11: 공람
D12: 처 리 과
D13: 담 당 자
A14: 제 목 : | B14: =개요!B9 | C14: 소방시설 점검 결과보고서 제출
A17: 1. 귀 대상물의 무궁한 발전을 기원합니다.
A19: 2. 귀 대상물의 소방시설점검에 대한 결과보고서를 아래의 붙임과 같이 제출하는
A20: 바입니다.
A23: 붙 임 : 1. 소방시설점검 결과보고서 1부
A24: 끝.
A33: 주식회사 승진소방 ENG
A34: 대표이사 김흥준(직인생략)

Sheet 대상물
A1: ■ 소방시설 자체점검사항 등에 관한 고시[별지 제4호서식]
A2: 소방시설등 | E2: 작동점검 | G2: [ ]
E3: 종합점검(최초점검) | G3: [ ] | H3: 그 밖의 점검 | L3: [ ] | M3: )점검표
A4: (7쪽 중 1쪽) ※ 소방시설, 다중이용업란의 [ ]란에는 해당 시설에 √ 표를 한다. 점검결과란은 양호○. 불량X. 해당없는 항목은 /표시를 한다.
A5: □ 특정소방대상물
A6: 건물명(상호) | E6: =개요!B14 | H6: 대상물 구분 | L6: =개요!B15
A7: 소 재 지 | E7: =개요!B16
A8: □ 소방시설등 점검결과
A9: 구분 | B9: 해 당 설 비 | G9: 점검결과 | H9: 구분 | I9: 해 당 설 비 | N9: 점검결과
A10: 소화 설비 | B10: =현황!C6 -> [ ] | C10: =현황!E6 -> 소화기구 및 자동소화장치 | H10: 피난 구조 설비 | I10: =현황!Y6 -> [ ] | J10: =현황!AA6 -> 피난기구
C11: =현황!D7 -> [ ] | D11: =현황!F7 -> 소화기구(소화기,자확,간이) | G11: =현황!S7 | J11: =현황!Z7 -> [ ] | K11: =현황!AB7 -> 공기안전매트·피난사다리 | N11: =현황!AO7
C12: =현황!D8 -> [ ] | D12: =현황!F8 -> 주거용주방자동소화장치 | G12: =현황!S8 | J12: =현황!Z8 -> 0 | K12: =현황!AB8 -> (간이)완강기·미끄럼대·구조대 | N12: =현황!AO8 -> 0
C13: =현황!D9 -> [ ] | D13: =현황!F9 -> 상업용주방자동소화장치 | G13: =현황!S9 | J13: =현황!Z9 -> [ ] | K13: =현황!AB9 -> 다수인피난장비 | N13: =현황!AO9
C14: =현황!D10 -> [ ] | D14: =현황!F10 -> 캐비닛형자동소화장치 | G14: =현황!S10 | J14: =현황!Z10 -> [ ] | K14: =현황!AB10 -> 승강식피난기 | N14: =현황!AO10
C15: =현황!D11 -> [ ] | D15: =현황!F11 -> 가스·분말·고체자동소화장치 | G15: =현황!S11 | J15: =현황!Z11 -> 0 | K15: =현황!AB11 -> 하향식피난구용내림식사다리 | N15: =현황!AO11 -> 0
B16: =현황!C12 -> [ ] | C16: =현황!E12 -> 옥내소화전설비 | G16: =현황!S12 | I16: =현황!Y12 -> [ ] | J16: =현황!AA12 -> 인명구조기구 | N16: =현황!AO12
B17: =현황!C13 -> [ ] | C17: =현황!E13 -> 스프링클러설비 | G17: =현황!S13 | I17: =현황!Y13 -> [ ] | J17: =현황!AA13 -> 유도등 | N17: =현황!AO13
B18: =현황!C14 -> [ ] | C18: =현황!E14 -> 간이스프링클러설비 | G18: =현황!S14 | I18: =현황!Y14 -> [ ] | J18: =현황!AA14 -> 유도표지 | N18: =현황!AO14
B19: =현황!C15 -> [ ] | C19: =현황!E15 -> 화재조기진압용스프링클러설비 | G19: =현황!S15 | I19: =현황!Y15 -> [ ] | J19: =현황!AA15 -> 피난유도선 | N19: =현황!AO15
B20: =현황!C16 -> [ ] | C20: =현황!E16 -> 물분무소화설비 | G20: =현황!S16 | I20: =현황!Y16 -> [ ] | J20: =현황!AA16 -> 비상조명등 | N20: =현황!AO16
B21: =현황!C17 -> [ ] | C21: =현황!E17 -> 미분무소화설비 | G21: =현황!S17 | I21: =현황!Y17 -> [ ] | J21: =현황!AA17 -> 휴대용비상조명등 | N21: =현황!AO17
B22: =현황!C18 -> [ ] | C22: =현황!E18 -> 포소화설비 | G22: =현황!S18 | H22: 소화용수 설 비 | I22: =현황!Y18 -> [ ] | J22: =현황!AA18 -> 상수도소화용수설비 | N22: =현황!AO18
B23: =현황!C19 -> [ ] | C23: =현황!E19 -> 이산화탄소소화설비 | G23: =현황!S19 | I23: =현황!Y19 -> [ ] | J23: =현황!AA19 -> 소화수조 및 저수조 | N23: =현황!AO19
B24: =현황!C20 -> [ ] | C24: =현황!E20 -> 할론소화설비 | G24: =현황!S20 | H24: 소화 활동 설비 | I24: =현황!Y20 -> [ ] | J24: =현황!AA20 -> 거실제연설비 | N24: =현황!AO20
B25: =현황!C21 -> [ ] | C25: =현황!E21 -> 할로겐화합물 및 불활성기체 소화설비 | G25: =현황!S21 | I25: =현황!Y21 -> [ ] | J25: =현황!AA21 -> 부속실 등 제연설비 | N25: =현황!AO21
B26: =현황!C22 -> [ ] | C26: =현황!E22 -> 분말소화설비 | G26: =현황!S22 | I26: =현황!Y22 -> [ ] | J26: =현황!AA22 -> 연결송수관설비 | N26: =현황!AO22
B27: =현황!C23 -> [ ] | C27: =현황!E23 -> 강화액소화설비 | G27: =현황!S23 | I27: =현황!Y23 -> [ ] | J27: =현황!AA23 -> 연결살수설비 | N27: =현황!AO23
B28: =현황!C24 -> [ ] | C28: =현황!E24 -> 고체에어로졸소화설비 | G28: =현황!S24 | I28: =현황!Y24 -> [ ] | J28: =현황!AA24 -> 비상콘센트설비 | N28: =현황!AO24
B29: =현황!C25 -> [ ] | C29: =현황!E25 -> 옥외소화전설비 | G29: =현황!S25 | I29: =현황!Y25 -> [ ] | J29: =현황!AA25 -> 무선통신보조설비 | N29: =현황!AO25
A30: 경보 설비 | B30: =현황!C26 -> [ ] | C30: =현황!E26 -> 단독경보형감지기 | G30: =현황!S26 | I30: =현황!Y26 -> [ ] | J30: =현황!AA26 -> 연소방지설비 | N30: =현황!AO26
B31: =현황!C27 -> [ ] | C31: =현황!E27 -> 비상경보설비 | G31: =현황!S27 | H31: 기 타 | I31: =현황!Y27 -> [ ] | J31: =현황!AA27 -> 방화문, 방화셔터 | N31: =현황!AO27
B32: =현황!C28 -> [ ] | C32: =현황!E28 -> 자동화재탐지설비 및 시각경보기 | G32: =현황!S28 | I32: =현황!Y28 -> [ ] | J32: =현황!AA28 -> 비상구, 피난통로 | N32: =현황!AO28
B33: =현황!C29 -> [ ] | C33: =현황!E29 -> 비상방송설비 | G33: =현황!S29 | I33: =현황!Y29 -> [ ] | J33: =현황!AA29 -> 방 염 | N33: =현황!AO29
B34: =현황!C30 -> [ ] | C34: =현황!E30 -> 통합감시시설 | G34: =현황!S30 | H34: 비 고
B35: =현황!C31 -> [ ] | C35: =현황!E31 -> 자동화재속보설비 | G35: =현황!S31
B36: =현황!C32 -> [ ] | C36: =현황!E32 -> 누전경보기 | G36: =현황!S32
B37: =현황!C33 -> [ ] | C37: =현황!E33 -> 가스누설경보기 | G37: =현황!S33

Sheet 대상물2
A1: □ 다중이용업소 안전시설등 점검결과 (7쪽 중 2쪽)
A2: 구분 | C2: 해 당 설 비 | F2: 점검결과 | G2: 구분 | I2: 해 당 설 비 | K2: 점검결과
A3: 소화 설비 | B3: =현황!C37 -> [ ] | C3: =현황!E37 -> 소화기 또는 자동확산소화기 | F3: =현황!S37 | G3: 비상구 | H3: =현황!Y37 -> [ ] | I3: =현황!AA37 -> 방화문 | K3: =현황!AO37
B4: =현황!C38 -> [ ] | C4: =현황!E38 -> 간이스프링클러설비 | F4: =현황!S38 | H4: =현황!Y38 -> [ ] | I4: =현황!AA38 -> 비상구(비상탈출구) | K4: =현황!AO38
A5: 경보 설비 | B5: =현황!C39 -> [ ] | C5: =현황!E39 -> 비상경보설비 또는 자동화재탐지설비 | F5: =현황!S39 | G5: 기 타 | H5: =현황!Y39 -> [ ] | I5: =현황!AA39 -> 영업장 내부 피난통로 | K5: =현황!AO39
B6: =현황!C40 -> [ ] | C6: =현황!E40 -> 가스누설경보기 | F6: =현황!S40 | H6: =현황!Y40 -> [ ] | I6: =현황!AA40 -> 영상음향차단장치 | K6: =현황!AO40
A7: 피난 구조 설비 | B7: =현황!C41 -> [ ] | C7: =현황!E41 -> 피난기구 | F7: =현황!S41 | H7: =현황!Y41 -> [ ] | I7: =현황!AA41 -> 누전차단기 | K7: =현황!AO41
B8: =현황!C42 -> [ ] | C8: =현황!E42 -> 피난유도선 | F8: =현황!S42 | H8: =현황!Y42 -> [ ] | I8: =현황!AA42 -> 창 문 | K8: =현황!AO42
B9: =현황!C43 -> [ ] | C9: =현황!E43 -> 유도등, 유도표지 또는 비상조명등 | F9: =현황!S43 | H9: =현황!Y43 -> [ ] | I9: =현황!AA43 -> 피난안내도, 피난안내영상물 | K9: =현황!AO43
B10: =현황!C44 -> [ ] | C10: =현황!E44 -> 휴대용비상조명등 | F10: =현황!S44 | H10: =현황!Y44 -> [ ] | I10: =현황!AA44 -> 방염물품 | K10: =현황!AO44
A11: 비 고 | B11: =현황!C45 -> 0
A13: □ 점검업체(점검인력) 현황
A14: 구 분 | D14: 성 명 | E14: 자격구분 | G14: 자격번호 | J14: 점검참여일(기간) | K14: 서명
A15: 주 인 력 | D15: =보고서!C17 -> 김흥준 | E15: =보고서!D17 -> 소방시설관리사 | G15: =보고서!E17 -> 제2005-60호 | J15: =보고서!F17
A16: 보조인력 | D16: =보고서!C18 | E16: =보고서!D18 -> 점검자경력수첩 | G16: =보고서!E18 | J16: =보고서!F18
A17: 보조인력 | D17: =보고서!C19 | E17: =보고서!D19 -> 점검자경력수첩 | G17: =보고서!E19 | J17: =보고서!F19
A18: 보조인력 | D18: =보고서!C20 | E18: =보고서!D20 -> 점검자경력수첩 | G18: =보고서!E20 | J18: =보고서!F20
A19: 보조인력 | D19: =개요!B5 | E19: =개요!C5 -> 점검자경력수첩 | G19: =개요!D5 | J19: =보고서!F21
A20: 보조인력 | D20: =개요!B6 | E20: =개요!C6 -> 점검자경력수첩 | G20: =개요!D6 | J20: =보고서!F23
A21: 보조인력 | D21: =개요!B8 | E21: =개요!C8 -> 점검자경력수첩 | G21: =개요!D8 | J21: =보고서!F24
A22: 점검기간(일자): | D22: =개요!E1 | J22: ( 총 점검기간 : | K22: =개요!F1
A23: 소방시설관리업체(등록번호): 승진소방 ENG (제 경기양평-2020-01호) 대 표 자: 김 흥 준 (인)
A24: 점검번호 구분
A25: 대분류 (설비구분) | D25: 소화기구 및 자동소화장치를‘1’번으로 하여 설비별 순차적으로 번호를 부여하여 다중이용업소‘32’번까지로 함
A26: 중분류 (단위구분) | D26: 각 설비별 점검단위에 따라‘A’부터 알파벳 순서대로 부여함
A27: 소분류 (점검항목) | D27: 각 설비별 점검단위 내의 점검항목에 따라‘001’부터 순서대로 부여함
A29: 작성 및 유의사항
A30: 1. 소방시설등 (작동, 종합)점검결과보고서의 ‘각 설비별 점검결과’에는 본 서식의 점검번호를 기재한다. 2. 자체점검결과(보고서 및 점검표)를 2년간 보관하여야 한다.

Sheet 세1
A1: 소방시설등의 세부현황 | S1: (7쪽 중 3쪽)
A2: ※[ ]에는 해당 시설에√표를 하고, 수량을 기입하며, 설비현황에 대하여 기입란이 부족한 경우 서식을 추가하여 작성할 수 있습니다.
A3: 1. 소화기구, 자동소화장치
A4: 구분 | B4: =현1!B3 -> 0 | C4: =현1!C3 -> [ ] | D4: =현1!D3 -> 소화기 | J4: =현1!J3 -> [ ] | K4: =현1!K3 -> 간이소화용구 | O4: =현1!O3 -> [ ] | P4: 자동 | R4: =현1!R3 -> [ ] | S4: 자동 | T4: 비 고
B5: =현1!B4 -> [ ] | C5: 분말 | G5: =현1!G4 -> [ ] | H5: 기타 | I5: =현1!I4 -> [ ] | J5: 투척용 | L5: =현1!L4 -> [ ] | M5: 기타 | N5: 확산소화기 | Q5: 소화장치
A6: 합계 | B6: =현1!B5 -> 0 | G6: =현1!G5 -> 0 | I6: =현1!I5 -> 0 | L6: =현1!L5 -> 0 | N6: =현1!N5 -> 0 | Q6: =현1!Q5 -> 0 | T6: =현1!T5
A7: 동명
A8: =현1!A7 -> 1 | B8: =현1!B7 -> 0 | G8: =현1!G7 -> 0 | I8: =현1!I7 -> 0 | L8: =현1!L7 -> 0 | N8: =현1!N7 -> 0 | Q8: =현1!Q7 -> 0 | T8: =현1!T7
A9: =현1!A8 -> 2 | B9: =현1!B8 -> 0 | G9: =현1!G8 -> 0 | I9: =현1!I8 -> 0 | L9: =현1!L8 -> 0 | N9: =현1!N8 -> 0 | Q9: =현1!Q8 -> 0 | T9: =현1!T8 -> 0
A10: =현1!A9 -> 3 | B10: =현1!B9 -> 0 | G10: =현1!G9 -> 0 | I10: =현1!I9 -> 0 | L10: =현1!L9 -> 0 | N10: =현1!N9 -> 0 | Q10: =현1!Q9 -> 0 | T10: =현1!T9 -> 0
A11: =현1!A10 -> 4 | B11: =현1!B10 -> 0 | G11: =현1!G10 -> 0 | I11: =현1!I10 -> 0 | L11: =현1!L10 -> 0 | N11: =현1!N10 -> 0 | Q11: =현1!Q10 -> 0 | T11: =현1!T10 -> 0
A12: =현1!A11 -> 5 | B12: =현1!B11 -> 0 | G12: =현1!G11 -> 0 | I12: =현1!I11 -> 0 | L12: =현1!L11 -> 0 | N12: =현1!N11 -> 0 | Q12: =현1!Q11 -> 0 | T12: =현1!T11 -> 0
A13: =현1!A12 -> 6 | B13: =현1!B12 -> 0 | G13: =현1!G12 | I13: =현1!I12 -> 0 | L13: =현1!L12 | N13: =현1!N12 | Q13: =현1!Q12 | T13: =현1!T12 -> 0
A14: =현1!A13 -> 7 | B14: =현1!B13 -> 0 | G14: =현1!G13 | I14: =현1!I13 -> 0 | L14: =현1!L13 | N14: =현1!N13 | Q14: =현1!Q13 | T14: =현1!T13 -> 0
A15: =현1!A14 -> 8 | B15: =현1!B14 -> 0 | G15: =현1!G14 | I15: =현1!I14 | L15: =현1!L14 | N15: =현1!N14 | Q15: =현1!Q14 | T15: =현1!T14 -> 0
A16: 2. 수계소화설비(공통사항)
A17: 수원 | B17: 주된수원 | G17: =현1!G16 -> ◦ 설비의 종류: [ ]옥내소화전설비 [ ]옥외소화전설비 [ ]스프링클러설비
G18: =현1!G17 -> [ ]간이스프링클러설비 [ ]화재조기진압용스프링클러설비
G19: =현1!G18 -> [ ]물분무소화설비 [ ]미분무소화설비 [ ]포소화설비
G20: =현1!G19 -> ◦ 설치장소: 동명( ) [ ]지상/[ ]지하 ( )층, 실명( )
G21: =현1!G20 -> ◦ 흡입방식: [ ]정압 [ ]부압, ◦ 유효수량: ( )㎥
B22: 보조수원 | G22: =현1!G21 -> ◦ 설치장소: 동명( ) 실명( ), ◦ 유효수량: ( )㎥
A23: 가압 송수 장치 | B23: [ ]고가수조 | G23: =현1!G22 -> ◦ 설비의 종류: [ ]옥내소화전설비 [ ]옥외소화전설비 [ ]스프링클러설비
G24: =현1!G23 -> [ ]간이스프링클러설비 [ ]화재조기진압용스프링클러설비
G25: =현1!G24 -> [ ]물분무소화설비 [ ]미분무소화설비 [ ]포소화설비
G26: =현1!G25 -> ◦ 설치장소: 동명( ) 실명( ), ◦ 유효수량: ( )㎥
B27: [ ]압력수조 | G27: =현1!G26 -> ◦ 설비의 종류: [ ]옥내소화전설비 [ ]옥외소화전설비 [ ]스프링클러설비
G28: =현1!G27 -> [ ]간이스프링클러설비 [ ]화재조기진압용스프링클러설비
G29: =현1!G28 -> [ ]물분무소화설비 [ ]미분무소화설비 [ ]포소화설비
G30: =현1!G29 -> ◦ 설치장소: 동명( ) [ ]지상/[ ]지하 ( )층, 실명( )
G31: =현1!G30 -> ◦ 수조용량: ( )ℓ, 수조가압압력:( )Mpa
G32: =현1!G31 -> ◦ 자동식공기압축기 용량:( )㎥/min, 동 력:( )Kw
B33: [ ]가압수조 | G33: =현1!G32 -> ◦ 설비의 종류: [ ]옥내소화전설비 [ ]옥외소화전설비 [ ]스프링클러설비
G34: =현1!G33 -> [ ]간이스프링클러설비 [ ]화재조기진압용스프링클러설비
G35: =현1!G34 -> [ ]물분무소화설비 [ ]미분무소화설비 [ ]포소화설비
G36: =현1!G35 -> ◦ 설치장소: 동명( ) [ ]지상/[ ]지하 ( )층, 실명( )
G37: =현1!G36 -> ◦ 수조용량: ( )ℓ, 수조가압압력:( )Mpa
G38: =현1!G37 -> ◦ 가압가스의 종류: [ ]공기 [ ]불연성가스( )

Sheet 세2
I1: (7쪽 중 4쪽)
A2: 가압 송수 장치 | C2: =현2!C2 -> [ ]펌프방식 | D2: =현2!D2 -> ◦ 설비의 종류: [ ]옥내소화전설비 [ ]옥외소화전설비 [ ]스프링클러설비
D3: =현2!D3 -> [ ]간이스프링클러설비 [ ]화재조기진압용스프링클러설비
D4: =현2!D4 -> [ ]물분무소화설비 [ ]미분무소화설비 [ ]포소화설비
D5: =현2!D5 -> ◦ 설치장소: 동명( ) [ ]지상/[ ]지하 ( )층, 실명( )
D6: =현2!D6 -> ◦ 주펌프 전양정:( )m, 토출량:( )ℓ/min
D7: =현2!D7 -> [ ]전동기 [ ]내연기관(연료:[ ]경유 [ ]기타
D8: =현2!D8 -> ◦ 예비펌프 전양정:( )m, 토출량:( )ℓ/min
D9: =현2!D9 -> [ ]전동기 [ ]내연기관(연료:[ ]경유 [ ]기타
D10: =현2!D10 -> ◦ 충압펌프 전양정:( )m, 토출량:( )ℓ/min
D11: =현2!D11 -> ◦ [ ]물올림장치(유효수량: ( )ℓ, 급수배관: ( )㎜
D12: =현2!D12 -> ◦ 기동장치: [ ]기동용수압개폐장치, [ ]ON/OFF 방식
D13: =현2!D13 -> [ ]압력챔버(용량:( )ℓ, 사용압력:( )MPa)
D14: =현2!D14 -> [ ]기동용압력스위치([ ]부르동관식 [ ]전자식 [ ]그 밖의 것)
D15: =현2!D15 -> ◦ [ ]감압장치 [ ]지상/[ ]지하 ( )층, 설치장소:( )
A16: 송수구 | C16: =현2!C16 -> ◦ 설비의 종류: [ ]옥내소화전설비 [ ]옥외소화전설비 [ ]스프링클러설비
C17: =현2!C17 -> [ ]간이스프링클러설비 [ ]화재조기진압용스프링클러설비
C18: =현2!C18 -> [ ]물분무소화설비 [ ]미분무소화설비 [ ]포소화설비
C19: =현2!C19 -> ◦ 설치장소:( ), [ ]쌍구형 ( )개/[ ]단구형 ( )개
A20: 비상전원 | C20: =현2!C20 -> [ ]자가발전설비([ ]소방전용 [ ]소방부하겸용 [ ]소방전원보존형 [ ]기타( ))
C21: =현2!C21 -> [ ]비상전원수전설비 [ ]축전지설비 [ ]전기저장장치
C22: =현2!C22 -> ◦ 설치장소: 동명( ) [ ]지상/[ ]지하 ( )층, 실명( )
A23: 3. 수계소화설비(개별사항)
A24: =현2!A24 -> [ ] | B24: =현2!B24 -> 옥내소화전 | C24: =현2!C24 -> ◦ 설치장소: 동명( ) [ ]전체층/[ ]일부층 [ ]지상/[ ]지하( )층 ~ [ ]지상/[ ]지하( )층
C25: =현2!C25 -> 동명( ) [ ]전체층/[ ]일부층 [ ]지상/[ ]지하( )층 ~ [ ]지상/[ ]지하( )층
C26: =현2!C26 -> ◦ 설치개수가 가장 많은 층의 설치개수: ( )개
A27: =현2!A27 -> [ ] | B27: =현2!B27 -> 옥외소화전 | C27: =현2!C27 -> ◦ 설치개수: ( )개
A28: =현2!A28 -> [ ] | B28: =현2!B28 -> 스프링클러설비 | C28: =현2!C28 -> ◦ 종류: [ ]습식 [ ]부압식 [ ]준비작동식 [ ]건식 [ ]일제살수식
C29: =현2!C29 -> ◦ 설치장소: 동명( ) [ ]전체층/[ ]일부층 [ ]지상/[ ]지하( )층 ~ [ ]지상/[ ]지하( )층
A30: =현2!A30 -> [ ] | B30: =현2!B30 -> 간이 스프링클러설비 | C30: =현2!C30 -> ◦ 종류: [ ]펌프 [ ]캐비닛 [ ]상수도
C31: =현2!C31 -> ◦ 설치장소: 동명( ) [ ]전체층/[ ]일부층 [ ]지상/[ ]지하( )층 ~ [ ]지상/[ ]지하( )층
A32: =현2!A32 -> [ ] | B32: =현2!B32 -> 화재 조기진압용 | C32: =현2!C32 -> ◦ 설치장소: 동명( ) [ ]전체층/[ ]일부층 [ ]지상/[ ]지하( )층 ~ [ ]지상/[ ]지하( )층
C33: =현2!C33 -> 동명( ) [ ]전체층/[ ]일부층 [ ]지상/[ ]지하( )층 ~ [ ]지상/[ ]지하( )층
A34: =현2!A34 -> [ ] | B34: =현2!B34 -> 물분무 소화설비 | C34: =현2!C34 -> ◦ 설치장소: 동명( ) [ ]전체층/[ ]일부층 [ ]지상/[ ]지하( )층 ~ [ ]지상/[ ]지하( )층
C35: =현2!C35 -> 동명( ) [ ]전체층/[ ]일부층 [ ]지상/[ ]지하( )층 ~ [ ]지상/[ ]지하( )층
A36: =현2!A36 -> [ ] | B36: =현2!B36 -> 포 소화설비 | C36: =현2!C36 -> [ ]포워터스프링클러설비 [ ]포헤드설비 [ ]고정포방출설비 [ ]기타( )
C37: =현2!C37 -> ◦ 소화약제 [ ]단백포 [ ]합성계면활성제포 [ ]수성막포 [ ]내알코올포
C38: =현2!C38 -> ◦ 설치장소: 동명( ) [ ]전체층/[ ]일부층 [ ]지상/[ ]지하( )층 ~ [ ]지상/[ ]지하( )층

Sheet 세3
I1: (7쪽 중 5쪽)
A2: 4. 가스계소화설비(개별사항)
A3: =현2!A40 -> [ ] | B3: =현2!B40 -> 이산화탄소 | C3: =현2!C40 -> [ ]전역방출 [ ]국소방출 [ ]호스릴 / [ ]고압식 [ ]저압식 / [ ]축압식 [ ]가압식
A4: =현2!A41 -> [ ] | B4: =현2!B41 -> 할론 | C4: =현2!C41 -> ◦ 설치장소: 동명( ) [ ]전체층/[ ]일부층 [ ]지상/[ ]지하( )층 ~ [ ]지상/[ ]지하( )층
A5: =현2!A42 -> [ ] | B5: =현2!B42 -> 할로겐화합물 및 불활성기체 | C5: =현2!C42 -> ◦ 저장용기 설치장소: [ ]지상/[ ]지하 ( )층, [ ]전용실 [ ]기타( )
C6: =현2!C43 -> 수량: ( )[ ]㎏,[ ]㎥ ( )ℓ ( )개
A7: =현2!A44 -> [ ] | B7: =현2!B44 -> 분말 | C7: =현2!C44 -> ◦ 소화약제 [ ]이산화탄소 [ ]할론1301 [ ]할론2402 [ ]할론1211 [ ] 할론104
A8: =현2!A45 -> [ ] | B8: =현2!B45 -> 강화액 | C8: =현2!C45 -> [ ]FC-3-1-10 [ ]HCFC BLEND A [ ]HCFC-124 [ ]HFC-125 [ ]HFC-227ea
A9: =현2!A46 -> [ ] | B9: =현2!B46 -> 고체에어로졸 | C9: =현2!C46 -> [ ]HFC-23 [ ]IG-541 [ ]IG-100 [ ] 기타( )
A10: =현2!A47 -> 0 | C10: =현2!C47 -> [ ]제1종분말 [ ]제2종분말 [ ]제3종분말 [ ]제4종분말
A11: 5. 경보설비
A12: =현황!C26 -> [ ] | B12: =현3!B3 -> 단독 경보형감지기 | C12: =현3!C3 -> ◦ 설치장소: 동명( ) [ ]전체층/[ ]일부층 [ ]지상/[ ]지하( )층 ~ [ ]지상/[ ]지하( )층
C13: =현3!C4 -> ◦ 주전원 [ ]상용전원 [ ]건전지
A14: =현황!C27 -> [ ] | B14: =현3!B5 -> 비상경보설비 | C14: =현3!C5 -> [ ]비상벨설비 [ ]자동식사이렌설비
C15: =현3!C6 -> ◦ 설치장소: 동명( ) [ ]전체층/[ ]일부층 [ ]지상/[ ]지하( )층 ~ [ ]지상/[ ]지하( )층
C16: =현3!C7 -> ◦ 조작장치 설치장소: 동명( ) [ ]지상/[ ]지하 ( )층 실명( )
A17: =현황!C28 -> [ ] | B17: =현3!B8 -> 자동화재 탐지설비 | C17: =현3!C8 -> ◦ 수신기 위치: 동명( ) [ ]지상/[ ]지하 ( )층 실명( )
C18: =현3!C9 -> ◦ 경보방식 [ ]전층경보 [ ]우선경보, 시각경보기 [ ]유 [ ]무
C19: =현3!C10 -> ◦ 설치장소: 동명( ) [ ]전체층/[ ]일부층 [ ]지상/[ ]지하( )층 ~ [ ]지상/[ ]지하( )층
C20: =현3!C11 -> 동명( ) [ ]전체층/[ ]일부층 [ ]지상/[ ]지하( )층 ~ [ ]지상/[ ]지하( )층
C21: =현3!C12 -> ◦ 감지기종류 [ ]열 [ ]연기 [ ]그 밖의 것([ ]불꽃 [ ]아날로그식 [ ]복합형)
A22: =현황!C29 -> [ ] | B22: =현3!B13 -> 비상방송설비 | C22: =현3!C13 -> [ ]전용 [ ]겸용 / [ ]전층경보 [ ]우선경보
C23: =현3!C14 -> ◦ 증폭기 설치장소: 동명( ) [ ]지상/[ ]지하 ( )층, 실명( )
A24: =현황!C31 -> [ ] | B24: =현3!B15 -> 자동화재 속보설비 | C24: =현3!C15 -> ◦ 속보기 설치장소: 동명( ) [ ]지상/[ ]지하 ( )층, 실명( )
A25: =현황!C30 -> [ ] | B25: =현3!B16 -> 통합감시시설 | C25: =현3!C16 -> ◦ 주수신기 설치장소: 동명( ) [ ]지상/[ ]지하 ( )층, 실명( )
C26: =현3!C17 -> ◦ 부수신기 설치장소: 동명( ) [ ]지상/[ ]지하 ( )층, 실명( )
C27: =현3!C18 -> ◦ 정보통신망 [ ]광케이블 [ ]기타( ) / 예비선로 [ ]유 [ ]무
A28: =현황!C32 -> [ ] | B28: =현3!B19 -> 누전경보기 | C28: =현3!C19 -> ◦ 주수신기 설치장소: 동명( ) [ ]지상/[ ]지하 ( )층, 실명( )
C29: =현3!C20 -> ◦ 수신기 형식 [ ]1급 [ ]2급, 차단기구 [ ]무 [ ]유(설치장소: )
A30: =현황!C33 -> [ ] | B30: =현3!B21 -> 가스누설 경보기 | C30: =현3!C21 -> ◦ [ ]단독형 [ ]분리형, 사용가스종류 [ ]LNG [ ]LPG, 경계구역 수: ( )개
C31: =현3!C22 -> ◦ 수신기 설치장소: 동명( ) [ ]지상/[ ]지하 ( )층, 실명( )
C32: =현3!C23 -> ◦ 차단기구 [ ]무 [ ]유(설치장소: )

Sheet 세4
F1: (7쪽 중 6쪽)
A2: 6. 피난구조설비
A3: =현황!Y6 -> [ ] | B3: =현3!B25 -> 피난기구 | E3: =현3!C25 -> ◦ 종류: [ ]피난사다리 [ ]완강기 [ ]다수인피난장비 [ ]승강식피난기 [ ]미끄럼대
E4: =현3!C26 -> [ ]피난교 [ ]피난용트랩 [ ]구조대 [ ]간이완강기 [ ]공기안전매트
E5: =현3!C27 -> ◦ 설치장소: 동명( ) [ ]전체층/[ ]일부층 [ ]지상/[ ]지하( )층 ~ [ ]지상/[ ]지하( )층
E6: =현3!C28 -> 동명( ) [ ]전체층/[ ]일부층 [ ]지상/[ ]지하( )층 ~ [ ]지상/[ ]지하( )층
A7: =현황!Y12 -> [ ] | B7: =현3!B29 -> 인명 구조기구 | E7: =현3!C29 -> ◦ 종류: [ ]방열복/ 방화복 [ ]공기호흡기 [ ]인공소생기
E8: =현3!C30 -> ◦ 설치장소: 동명( ) [ ]전체층/[ ]일부층 [ ]지상/[ ]지하( )층 ~ [ ]지상/[ ]지하( )층
E9: =현3!C31 -> 동명( ) [ ]전체층/[ ]일부층 [ ]지상/[ ]지하( )층 ~ [ ]지상/[ ]지하( )층
E10: =현3!C32 -> ◦ 대상물의 용도: [ ] 5층이상 병원 [ ] 7층이상 관광호텔 [ ] 이산화탄소소화설비 설치
E11: =현3!C33 -> [ ] 지하역사·백화점·대형점포·쇼핑센타·지하상가·영화상영관
A12: =현황!Y13 -> [ ] | B12: =현3!B34 -> 유도등 | E12: =현3!C34 -> ◦ 종류: [ ]피난구 [ ]통로 [ ]객석유도등 [ ]유도표지 [ ]피난유도선
E13: =현3!C35 -> ◦ 설치장소: 동명( ) [ ]전체층/[ ]일부층 [ ]지상/[ ]지하( )층 ~ [ ]지상/[ ]지하( )층
A14: =현황!Y16 -> [ ] | B14: =현3!B36 -> 비상조명등 | E14: =현3!C36 -> ◦ 설치장소: 동명( ) [ ]전체층/[ ]일부층 [ ]지상/[ ]지하( )층 ~ [ ]지상/[ ]지하( )층
E15: =현3!C37 -> ◦ 비상전원 [ ]자가발전설비 [ ]축전지설비 [ ]내장형
A16: =현황!Y17 -> [ ] | B16: =현3!B38 -> 휴대용 비상조명등 | E16: =현3!C38 -> ◦ 설치장소: 동명( ) [ ]전체층/[ ]일부층 [ ]지상/[ ]지하( )층 ~ [ ]지상/[ ]지하( )층
E17: =현3!C39 -> ◦ 전원 [ ]건전지식 [ ]충전식 배터리식
A18: 7. 소화용수설비
A19: =현황!Y18 -> [ ] | B19: =현3!B41 -> 상수도 소화용수 | E19: =현3!C41 -> ◦ 설치장소:( ), 소화전 호칭지름: ( )㎜
A20: =현황!Y19 -> [ ] | B20: =현3!B42 -> 소화수조 | E20: =현3!C42 -> [ ]전용 [ ]겸용/[ ]흡수식 [ ]가압식/[ ]일반수조 [ ]그 밖의 것/유효수량:( )㎥
E21: =현3!C43 -> ◦ 가압송수장치 전양정:( )m, 토출량:( )ℓ/min, [ ]전동기/[ ]내연기관(연료:[ ]경유 [ ]기타)
E22: =현3!C44 -> ◦ [ ]물올림장치 유효수량: ( )ℓ, 급수배관: ( )㎜
E23: =현3!C45 -> ◦ 기동스위치 설치장소: [ ]채수구 부근 [ ]방재실 [ ]기타( )
E24: =현3!C46 -> ◦ 채수구 구경: ( )㎜, 흡수관 투입구: 가로 ( )㎝ 세로 ( )㎝/직경 ( )㎝
A25: 8. 소화활동설비
A26: =현4!A3 -> [ ] | B26: =현4!B3 -> 제 연 설 비 | C26: =현황!Y20 -> [ ] | D26: =현4!D3 -> 거 실 | E26: =현4!E3 -> ◦ 설치장소: 동명( ) [ ]전체층/[ ]일부층 [ ]지상/[ ]지하( )층 ~ [ ]지상/[ ]지하( )층
E27: =현4!E4 -> ◦ 방식 [ ]단독 [ ]공동 [ ]상호 [ ]기타( )
E28: =현4!E5 -> ◦ 기동장치 [ ]자동(감지기 연동) [ ]수동 [ ]원격
E29: =현4!E6 -> ◦ 제연구획면적 최대: ( )㎡ / 구조 [ ]내화 [ ]불연 [ ]그 밖의 것:( )
E30: =현4!E7 -> ◦ 제연구역 출입문 [ ]상시폐쇄(자동폐쇄장치) [ ]상시개방(감지기에 의한 닫힘)
E31: =현4!E8 -> ◦ 급기용송풍기 설치장소: 동명( ) [ ]지상/[ ]지하 ( )층, 실명( )
E32: =현4!E9 -> 전동기 ( )㎾, 풍량 ( )㎥/min, 정압 ( )㎜Aq
E33: =현4!E10 -> ◦ 배출용송풍기 설치장소: 동명( ) [ ]지상/[ ]지하 ( )층, 실명( )
E34: =현4!E11 -> 전동기 ( )㎾, 풍량 ( )㎥/min, 정압 ( )㎜Aq
E35: =현4!E12 -> ◦ 배출구 [ ]천장면 [ ]천장직하 [ ]기타( ) / 옥외배출구 [ ]옥상 [ ]기타( )
E36: =현4!E13 -> 풍도구조 [ ]내화 [ ]불연 [ ]그 밖의 것( ) / 구획댐퍼 [ ]유 [ ]무
E37: =현4!E14 -> ◦ 유입공기배출 [ ]자연배출 [ ]기계배출 [ ]배출구 [ ]제연설비
E38: =현4!E15 -> ◦ 급기구 [ ]강제유입 [ ]자연유입 [ ]인접구역유입
E39: =현4!E16 -> 풍도구조 [ ]내화 [ ]불연 [ ]그 밖의 것( ) / 구획댐퍼 [ ]유 [ ]무

Sheet 세5
F1: (7쪽 중 7쪽)
A2: =현4!A3 -> [ ] | B2: 제 연 설 비 | C2: =현황!Y21 -> [ ] | D2: =현4!D17 -> 전 실 | E2: =현4!E17 -> ◦ 설치장소: 동명( , , , , )
E3: =현4!E18 -> 특별피난계단 ( )개소, 비상용승강기 ( )대
E4: =현4!E19 -> ◦ 방식 [ ]부속실 [ ]계단실 및 부속실 [ ] 계단실 [ ] 비상용승강기승강장
E5: =현4!E20 -> ◦ 기동방식 [ ]전층 [ ]부분층( 개층) / 댐퍼개방감지기 [ ]전용 [ ]겸용
E6: =현4!E21 -> ◦ 급기용송풍기 설치장소: 동명( ) [ ]지상/[ ]지하 ( )층, 실명( )
E7: =현4!E22 -> 전동기 ( )㎾, 풍량 ( )㎥/min, 정압 ( )㎜Aq
E8: =현4!E23 -> ◦ 배출용송풍기 설치장소: 동명( ) [ ]지상/[ ]지하 ( )층, 실명( )
E9: =현4!E24 -> 전동기 ( )㎾, 풍량 ( )㎥/min, 정압 ( )㎜Aq
E10: =현4!E25 -> ◦ 제연구역 출입문 [ ]상시폐쇄(자동폐쇄장치) [ ]상시개방(연기감지기에 의한 닫힘)
E11: =현4!E26 -> ◦ 유입공기배출 [ ]자연배출 [ ]기계배출 [ ]배출구 [ ]제연설비
E12: =현4!E27 -> ◦ 과압방지장치 [ ]플랩댐퍼 [ ]자동차압(과압조절형)댐퍼 [ ]그 밖의 것 [ ]해당없음
A13: =현황!Y22 -> [ ] | B13: =현4!B28 -> 연결송수관 | E13: =현4!E28 -> [ ]전용 [ ]겸용([ ]옥내소화전설비 [ ]스프링클러설비 [ ]기타: )
E14: =현4!E29 -> ◦ 설치장소: 동명( ) [ ]전체층/[ ]일부층 [ ]지상/[ ]지하( )층 ~ [ ]지상/[ ]지하( )층
E15: =현4!E30 -> ◦ 방수구 위치 [ ]복도·통로 [ ]계단실 [ ] 계단등의 부근
E16: =현4!E31 -> ◦ 송수구 설치장소:( ), 중간수조용량: ( )㎥
E17: =현4!E32 -> ◦ 가압송수장치 설치장소: 동명( ) [ ]지상/[ ]지하 ( )층, 실명( )
E18: =현4!E33 -> 전양정:( )m, 토출량:( )ℓ/min
E19: =현4!E34 -> [ ]전동기 [ ]내연기관(연료:[ ]경유 [ ]기타)
E20: =현4!E35 -> ◦ 기동스위치 설치장소 [ ]송수구 [ ]방재실 [ ]기타( )
A21: =현황!Y23 -> [ ] | B21: =현4!B36 -> 연결살수 | E21: =현4!E36 -> ◦ 설치장소: 동명( , , , , )
E22: =현4!E37 -> ◦ 방식 [ ]습식 [ ]건식 / [ ]지하층 [ ]판매시설 [ ]가스시설 [ ]부속된 연결통로
E23: =현4!E38 -> ◦ 송수구 설치장소:( ), 송수구역수: ( )구역
A24: =현황!Y24 -> [ ] | B24: =현4!B39 -> 비상콘센트 | E24: =현4!E39 -> ◦ 설치장소: 동명( ) [ ]지상/[ ]지하( )층 ~ [ ]지상/[ ]지하( )층
E25: =현4!E40 -> [ ]3상 380V [ ]단상 220V / [ ]접지형 2극 플러그접속기 [ ]접지형 3극 플러그접속기
A26: =현황!Y25 -> [ ] | B26: =현4!B41 -> 무선통신 보조 | E26: =현4!E41 -> ◦ 설치장소: 동명( ) [ ]지상/[ ]지하( )층 ~ [ ]지상/[ ]지하( )층
E27: =현4!E42 -> [ ]전용 [ ]공용 / 방식: [ ]누설동축케이블 [ ]누설동축케이블과 안테나 [ ]안테나
E28: =현4!E43 -> ◦ 접속단자 설치장소( ), ( )
A29: =현황!Y26 -> [ ] | B29: =현4!B44 -> 연소방지 | E29: =현4!E44 -> ◦ 방호대상물 [ ]전력사업용 [ ]통신사업용 [ ]그 밖의 것( )
E30: =현4!E45 -> ◦ 송수구역수: ( )구역 / 구역간의 구획 [ ]있다 [ ]일부 있다 [ ]없다
A31: 비고 | E31: ※ 제연설비 설비개요 작성 시 최대 구역 1개소에 대하여 기입합니다.

Sheet 목차
A1: - 목 차 -
A2: 1. 소화기구 및 자동소화장치 점검표
A3: 2. 옥내소화전설비 점검표
A4: 3. 스프링클러소화설비 점검표
A5: 4. 간이스프링클러소화설비 점검표
A6: 5. 할로겐화합물 및 불활성기체소화설비 점검표
A7: 6. 옥외소화전설비 점검표
A8: 7. 비상경보설비 및 단독경보형감지기 점검표
A9: 8. 자동화재탐지설비 및 시각경보장치 점검표
A10: 9. 비상방송설비 점검표
A11: 10. 자동화재속보설비 및 통합감시시설 점검표
A12: 11. 가스누설경보기 점검표
... A23: 22. 다중이용업소 점검표

Sheet Sheet1

Sheet 위임장
A1: 소방시설등 | D1: =대상물!G2 -> [ ] | G1: 작동 | K1: 점검결과 보고서 제출용 위임장
D2: =대상물!G3 -> [ ] | G2: 최초
D3: =대상물!L3 -> [ ] | G3: 종합
A5: 특정소방대상물 관계인(본인) | K5: 소방시설관리업체(대리인)
A6: 성 명 | C6: =개요!D10 | K6: 성명
A7: 직 위 | C7: =개요!D11 | K7: 직위
A8: 연락처 | C8: =개요!D12 | K8: 연락처
A9: 생년월일 | C9: =개요!D13 | K9: 생년월일
A10: 점검일자 | C10: =개요!E1 | S10: ( | T10: =개요!F1
A11: 위임내용
A12: 상기 본인은소방시설 설치 및관리에 관한 법률 제22조 제1항 따라 실시한
A13: 소방시설등의 자체점검과 관련하여 대리인이 실시한 자체점검 내용 일체를 확인하였으며, 같은
A14: 법 시행규칙 제23조에 따른 점검결과보고서의 제출을 대리인에게 위임합니다.
P15: =개요!B10
L17: 관계인 | O17: =개요!D10 | T17: (서명 또는 인)
P19: =개요!D14 | S19: 소방서(본부) 귀하
A20: 붙임서류 | B20: 소방시설등 점검결과 보고서 제출을 위임한 관계인 신분증명서 사본 1부
A21: 유의사항
A22: 1. 다른 사람의 인장 도용 등 허위로 위임장을 작성하여 신청할 경우에는 「형법」 제231조와 제232조에 따라 사문서 위조ㆍ변조죄로 5년 이하의 징역 또는 1천만원 이하의 벌금에 처하게 됩니다.
A23: 2. 자체점검 결과보고서를 보고기한 내에 제출하지 않으면, 이를 대리인에게 위임한 경우라도「질서위반행위규제법」제11조 제1항에 따라 제출의무가 있는 관계인이 100만원 이하의 과태료를 부과받게 됩니다.
A24: 210mm×297mm[백상지 80g/㎡(재활용품)]

Sheet 계획서
A1: ■ 소방시설 설치 및 관리에 관한 법률 시행규칙 [별지 제10호서식]
A2: 소방시설등의 자체점검 결과 이행계획서
A4: 특정소방 대상물 | B4: 대상물 명칭(상호) | K4: 대상물 구분(용도)
B5: =개요!B14 | K5: =개요!B15
B6: 관계인 | K6: 소방안전관리자
B7: (성명: | C7: =개요!B17 | E7: 전화번호: | H7: =개요!B19 | J7: ) | K7: (성명: | M7: =개요!B17 | N7: 전화번호 : | P7: =개요!B19 | S7: )
B8: 소재지
B9: =개요!B16
A11: 이행조치 계획사항 | B11: 이행조치 사항 | K11: 이행조치 일자
C12: =현5!A4 -> 소화설비 | G12: : | H12: =현5!C4 | K12: =B26 | O12: ~ | P12: =J26
N13: (총 | O13: =P26 | P13: 일 )
C14: =현5!A5 -> 경보설비 | G14: : | H14: =현5!C5 | K14: =B26 | O14: ~ | P14: =J26
N15: (총 | O15: =P26 | P15: 일 )
C16: =현5!A6 -> 피난구조설비 | G16: : | H16: =현5!C6 | K16: =B26 | O16: ~ | P16: =J26
N17: (총 | O17: =P26 | P17: 일 )
C18: =현5!A7 -> 소화용수설비 | G18: : | H18: =현5!C7 | K18: =B26 | O18: ~ | P18: =J26
N19: (총 | O19: =P26 | P19: 일 )
C20: =현5!A8 -> 소화활동설비 | G20: : | H20: =현5!C8 | K20: =B26 | O20: ~ | P20: =J26
N21: (총 | O21: =P26 | P21: 일 )
C22: =현5!A9 -> 기타 | G22: : | H22: =현5!C9 | K22: =B26 | O22: ~ | P22: =J26
N23: (총 | O23: =P26 | P23: 일 )
C24: =현5!A10 -> 안전시설등 | G24: : | H24: =현5!C10 | K24: =B26 | O24: ~ | P24: =J26
N25: (총 | O25: =P26 | P25: 일 )
A26: 이행조치 필요기간 | B26: =개요!G9 | H26: ~ | J26: =개요!I9 | O26: (총 | P26: =개요!J9 | Q26: 일)
A29: 「소방시설 설치 및 안전관리에 관한 법률」 제23조제3항 및 같은 법 시행규칙 제23조제2항에 따라 위와 같이 소방시설등의 수리ㆍ교체ㆍ정비에 대한 이행계획서를 제출합니다.
L30: =개요!B10
I31: 관계인: | L31: =C7 | P31: (서명 또는 인)
A33: =개요!D14 | B33: 소방서장 귀하
A35: 유의사항
A36: 「소방시설 설치 및 관리에 관한 법률」 제61조제1항 제8호 및 제9호 | B36: 1. 특정소방대상물의 관계인이 법 제22조에 따른 소방시설등의 자체점검 결과에 따른 수리ㆍ조치ㆍ정비사항의
B37: 발생 시 이행계획서를 첨부하지 않거나 거짓으로 제출한 경우 300만원 이하의 과태료를 부과합니다.
B39: 2. 특정소방대상물의 관계인이 소방시설등의 수리ㆍ조치ㆍ정비 이행계획을 별도의 연기신청 없이 기간 내에 완
B40: 료하지 않은 경우 300만원 이하의 과태료를 부과합니다.
H41: 210mm×297mm[백상지(80g/㎡) 또는 중질지(80g/㎡)]

Sheet 완료보고서
A1: ■ 소방시설 설치 및 관리에 관한 법률 시행규칙 [별지 제11호서식]
A2: 소방시설등의 자체점검 결과 이행완료 보고서
A4: 특정소방 대상물 | B4: 대상물 명칭(상호) | I4: 대상물 구분(용도)
B5: =계획서!B5 | I5: =계획서!K5
B6: 관계인 | I6: 소방안전관리자
B7: (성명: 전화번호: ) | C7: =계획서!C7 | E7: 전화번호: | F7: =계획서!H7 | H7: ) | I7: 성명: | J7: =개요!B17
I8: 전화번호: | J8: =개요!B19
B9: 소재지
B10: =계획서!B9
A11: 소방공사 업체 | B11: 업체명(상호) | I11: 사업자번호
B12: ㈜승진소방ENG | I12: 586-86-00740
B13: 대표이사
B14: (성명: 전화번호: ) | C14: 김흥준 | E14: 전화번호: | F14: 031-772-3019 | H14: )
B15: 소재지
B16: 경기도 양평군 양평읍 잿말길10번길 50-1 (덕평리 98-1)
A18: 이행완료 사항 | B18: 이행조치 내용 | I18: 이행조치 일자
I20: =개요!G10
A24: 「소방시설 설치 및 안전관리에 관한 법률」 제23조제4항 및 같은 법 시행규칙 제23조제6항에 따라 위와 같이 소방시설등의 수리ㆍ교체ㆍ정비에 대한 이행완료 보고서를 제출합니다.
G25: =개요!G10+5
F27: 관계인: | H27: =C7 | K27: (서명 또는 인)
A29: =개요!D14 | B29: 소방서장 귀하
A31: 첨부서류 | B31: 1. 이행계획 건별 이행 전ㆍ후 사진 증명자료 1부
B32: 2. 소방시설공사 계약서(이행조치 내용과 관련됩니다) 1부
A33: 유의사항
A34: 「소방시설 설치 및 관리에 관한 법률」 제61조제1항 제8호 및 제9호 | B34: 1. 특정소방대상물의 관계인이 법 제22조에 따른 소방시설등의 자체점검 결과에 따른 수리ㆍ조치ㆍ정비사항 발생 시 이행계획서를 첨부하지 않거나 거짓으로 제출한 경우 300만원 이하의 과태료를 부과합니다.
B36: 2. 특정소방대상물의 관계인이 소방시설등의 수리ㆍ조치ㆍ정비 이행계획을 별도의 연기신청 없이 기간 내에 완료하지 않은 경우 300만원 이하의 과태료를 부과합니다.
F37: 210mm×297mm[백상지(80g/㎡) 또는 중질지(80g/㎡)]

Sheet 계약서
A1: 소 방 시 설 보 수 계 약 서
A3: =개요!B14 | C3: (이하 "발주처"라 칭함)과 ㈜승진소방ENG(이하 "계약대상자"라 칭함)
A4: 아래와 같이 소방시설물 보수 용역계약을 체결함에 있어 계약체결의 증표로써 본 계약서 2부를
A5: 작성하여 쌍방이 서명 날인하고 "발주처"."계약대상자"가 1부씩 보관한다.
A7: 계약내용 | B7: 1. | C7: 계약명 | D7: 소방보수
B8: 2. | C8: 주 소 | D8: =개요!B16
B9: 3. | C9: 건축물 개요 | D9: =개요!B15
B10: 4. | C10: 보수기간 | D10: =개요!G9 | F10: ~ | G10: =개요!I9
B11: 5. | C11: 보수금액 | D11: 일금 | E11: =NUMBERSTRING(J11,1)&" 원정" | I11: ( | K11: )
B12: 6. | C12: 선급금 | D12: 일금 | I12: ( | K12: )
B13: 7. | C13: 중도금 | D13: 일금 | I13: ( | K13: )
B14: 8. | C14: 잔금 | D14: 일금 | E14: =NUMBERSTRING(J14,1)&" 원정" | I14: ( | K14: )
E15: (VAT별도) (공사완료후 30일이내)
A16: 기타사항 | B16: 본 공사 이행에 필요한 사항은 별첨 협약서에 의한다.
A18: 첨 부 | C18: 1. 협약서 1부
C20: 작성일자 | D20: =개요!B10
A23: 발 주 처 | C23: 주 소 : | D23: =D8
C24: 상 호 : | D24: =A3 | G24: 연락처: | H24: =개요!B19
C25: 담 당 자 : | D25: =개요!B17 | F25: (서명 또는 날인)
A27: 계약대상자 | C27: 주 소 : | D27: 경기도 양평군 양평읍 잿말길10번길 50-1
C28: 상 호 : | D28: ㈜승진소방이엔지 | G28: 연락처 : | H28: 031-772-3019
C29: 대 표 자 : | F29: (인) | G29: 팩 스 : | H29: 031-772-2419

Sheet 목 차
A1: - 목 차 -
A2: 1. 소화기구 및 자동소화장치 점검표
A3: 2. 옥내소화전설비 점검표
A4: 3. 스프링클러소화설비 점검표
A5: 4. 간이스프링클러소화설비 점검표
A6: 11. 할로겐화합물 및 불활성기체소화설비 점검표
A7: 13. 옥외소화전설비 점검표
A8: 14. 비상경보설비 및 단독경보형감지기 점검표
A9: 15. 자동화재탐지설비 및 시각경보장치 점검표
A10: 16. 비상방송설비 점검표
A11: 17. 자동화재속보설비 및 통합감시시설 점검표
A12: 19. 가스누설경보기 점검표
... A23: 32. 다중이용업소 점검표

Sheet 소
A1: 1. 소화기구 및 자동소화장치 점검표
A2: 번호 | B2: 점검항목 | C2: 점검결과
A3: 1-A. 소화기구(소화기, 자동확산소화기, 간이소화용구)
A4: 1-A-001 | B4: ○ 거주자 등이 손쉽게 사용할 수 있는 장소에 설치되어 있는지 여부
A5: 1-A-002 | B5: ○ 설치높이 적합 여부
A6: 1-A-003 | B6: ○ 배치거리(보행거리 소형 20m 이내, 대형 30m 이내) 적합 여부
A7: 1-A-004 | B7: ○ 구획된 거실(바닥면적 33㎡ 이상)마다 소화기 설치 여부
A8: 1-A-005 | B8: ○ 소화기 표지 설치상태 적정 여부
A9: 1-A-006 | B9: ○ 소화기의 변형·손상 또는 부식 등 외관의 이상 여부
A10: 1-A-007 | B10: ○ 지시압력계(녹색범위)의 적정 여부
A11: 1-A-008 | B11: ○ 수동식 분말소화기 내용연수(10년) 적정 여부
A12: 1-A-009 | B12: ● 설치수량 적정 여부
A13: 1-A-010 | B13: ● 적응성 있는 소화약제 사용 여부
A14: 1-B. 자동소화장치
B15: [주거용 주방 자동소화장치]
A16: 1-B-001 | B16: ○ 수신부의 설치상태 적정 및 정상(예비전원, 음향장치 등) 작동 여부 | F16: ○
A17: 1-B-002 | B17: ○ 소화약제의 지시압력 적정 및 외관의 이상 여부 | F17: /
A18: 1-B-003 | B18: ○ 소화약제 방출구의 설치상태 적정 및 외관의 이상 여부 | F18: ×
A19: 1-B-004 | B19: ○ 감지부 설치상태 적정 여부
A20: 1-B-005 | B20: ○ 탐지부 설치상태 적정 여부
A21: 1-B-006 | B21: ○ 차단장치 설치상태 적정 및 정상 작동 여부
B22: [상업용 주방 자동소화장치]
A23: 1-B-011 | B23: ○ 소화약제의 지시압력 적정 및 외관의 이상 여부
A24: 1-B-012 | B24: ○ 후드 및 덕트에 감지부와 분사헤드의 설치상태 적정 여부
A25: 1-B-013 | B25: ○ 수동기동장치의 설치상태 적정 여부
B26: [캐비닛형 자동소화장치]
A27: 1-B-021 | B27: ○ 분사헤드의 설치상태 적합 여부
A28: 1-B-022 | B28: ○ 화재감지기 설치상태 적합 여부 및 정상 작동 여부
A29: 1-B-023 | B29: ○ 개구부 및 통기구 설치 시 자동폐쇄장치 설치 여부
B30: [가스·분말·고체에어로졸 자동소화장치]
A31: 1-B-031 | B31: ○ 수신부의 정상(예비전원, 음향장치 등) 작동 여부
A32: 1-B-032 | B32: ○ 소화약제의 지시압력 적정 및 외관의 이상 여부
A33: 1-B-033 | B33: ○ 감지부(또는 화재감지기) 설치상태 적정 및 정상 작동 여부
A34: 비 고
A35: ※ 점검항목 중 “●”는 종합정밀점검의 경우에만 해당한다. ※ 점검결과란은 양호 “○”, 불량 “×”, 해당없는 항목은 “/”로 표시한다. ※ 점검항목 내용 중 “설치기준” 및 “설치상태”에 대한 점검은 정상적인 작동 가능 여부를 포함한다. ※ ‘비고’란에는 특정소방대상물의 위치․구조․용도 및 소방시설의 상황 등이 이 표의 항목대로 기재하기 곤란하거나 이 표에서 누락된 사항을 기재한다.(이하 같다)

Sheet 옥1
A1: 2. 옥내소화전설비 점검표
A2: 번호 | B2: 점검항목 | C2: 점검결과
A3: 2-A. 수원
A4: 2-A-001 | B4: ○ 주된수원의 유효수량 적정 여부(겸용설비 포함) | E4: ○
A5: 2-A-002 | B5: ○ 보조수원(옥상)의 유효수량 적정 여부 | E5: /
A6: 2-B. 수조 | E6: ×
A7: 2-B-001 | B7: ● 동결방지조치 상태 적정 여부
A8: 2-B-002 | B8: ○ 수위계 설치상태 적정 또는 수위 확인 가능 여부
A9: 2-B-003 | B9: ● 수조 외측 고정사다리 설치상태 적정 여부(바닥보다 낮은 경우 제외)
A10: 2-B-004 | B10: ● 실내설치 시 조명설비 설치상태 적정 여부
A11: 2-B-005 | B11: ○“옥내소화전설비용 수조”표지 설치상태 적정 여부
A12: 2-B-006 | B12: ● 다른 소화설비와 겸용 시 겸용설비의 이름 표시한 표지 설치상태 적정 여부
A13: 2-B-007 | B13: ● 수조-수직배관 접속부분“옥내소화전설비용 배관”표지 설치상태 적정 여부
A14: 2-C. 가압송수장치
B15: [펌프방식]
A16: 2-C-001 | B16: ● 동결방지조치 상태 적정 여부
A17: 2-C-002 | B17: ○ 옥내소화전 방수량 및 방수압력 적정 여부
A18: 2-C-003 | B18: ● 감압장치 설치 여부(방수압력 0.7MPa 초과 조건)
A19: 2-C-004 | B19: ○ 성능시험배관을 통한 펌프 성능시험 적정 여부
A20: 2-C-005 | B20: ● 다른 소화설비와 겸용인 경우 펌프 성능 확보 가능 여부
A21: 2-C-006 | B21: ○ 펌프 흡입측 연성계·진공계 및 토출측 압력계 등 부속장치의 변형·손상 유무
A22: 2-C-007 | B22: ● 기동장치 적정 설치 및 기동압력 설정 적정 여부
A23: 2-C-008 | B23: ○ 기동스위치 설치 적정 여부(ON/OFF 방식)
A24: 2-C-009 | B24: ● 주펌프와 동등이상 펌프 추가설치 여부
A25: 2-C-010 | B25: ● 물올림장치 설치 적정(전용 여부, 유효수량, 배관구경, 자동급수) 여부
A26: 2-C-011 | B26: ● 충압펌프 설치 적정(토출압력, 정격토출량) 여부
A27: 2-C-012 | B27: ○ 내연기관 방식의 펌프 설치 적정(정상기동(기동장치 및 제어반) 여부, 축전지상태, 연료량) 여부
A28: 2-C-013 | B28: ○ 가압송수장치의“옥내소화전펌프”표지설치 여부 또는 다른 소화설비와 겸용 시 겸용설비 이름 표시 부착 여부
B29: [고가수조방식]
A30: 2-C-021 | B30: ○ 수위계·배수관·급수관·오버플로우관·맨홀 등 부속장치의 변형·손상 유무
B31: [압력수조방식]
A32: 2-C-031 | B32: ● 압력수조의 압력 적정 여부
A33: 2-C-032 | B33: ○ 수위계·급수관·급기관·압력계·안전장치·공기압축기 등 부속장치의 변형· 손상유무
B34: [가압수조방식]
A35: 2-C-041 | B35: ● 가압수조 및 가압원 설치장소의 방화구획 여부
A36: 2-C-042 | B36: ○ 수위계·급수관·배수관·급기관·압력계 등 부속장치의 변형·손상 유무

Sheet 옥2
A1: (2면)
A2: 번호 | B2: 점검항목 | C2: 점검결과
A3: 2-D. 송수구
A4: 2-D-001 | B4: ○ 설치장소 적정 여부 | E4: ○
A5: 2-D-002 | B5: ● 연결배관에 개폐밸브를 설치한 경우 개폐상태 확인 및 조작가능 여부 | E5: /
A6: 2-D-003 | B6: ● 송수구 설치 높이 및 구경 적정 여부 | E6: ×
A7: 2-D-004 | B7: ● 자동배수밸브(또는 배수공)·체크밸브 설치 여부 및 설치 상태 적정 여부
A8: 2-D-005 | B8: ○ 송수구 마개 설치 여부
A9: 2-E. 배관 등
A10: 2-E-001 | B10: ● 펌프의 흡입측 배관 여과장치의 상태 확인
A11: 2-E-002 | B11: ● 성능시험배관 설치(개폐밸브, 유량조절밸브, 유량측정장치) 적정 여부
A12: 2-E-003 | B12: ● 순환배관 설치(설치위치·배관구경, 릴리프밸브 개방압력) 적정 여부
A13: 2-E-004 | B13: ● 동결방지조치 상태 적정 여부
A14: 2-E-005 | B14: ○ 급수배관 개폐밸브 설치(개폐표시형, 흡입측 버터플라이 제외) 적정 여부
A15: 2-E-006 | B15: ● 다른 설비의 배관과의 구분 상태 적정 여부
A16: 2-F. 함 및 방수구 등
A17: 2-F-001 | B17: ○ 함 개방 용이성 및 장애물 설치 여부 등 사용 편의성 적정 여부
A18: 2-F-002 | B18: ○ 위치·기동 표시등 적정 설치 및 정상 점등 여부
A19: 2-F-003 | B19: ○“소화전”표시 및 사용요령(외국어 병기) 기재 표지판 설치상태 적정 여부
A20: 2-F-004 | B20: ● 대형공간(기둥 또는 벽이 없는 구조) 소화전 함 설치 적정 여부
A21: 2-F-005 | B21: ● 방수구 설치 적정 여부
A22: 2-F-006 | B22: ○ 함 내 소방호스 및 관창 비치 적정 여부
A23: 2-F-007 | B23: ○ 호스의 접결상태, 구경, 방수 압력 적정 여부
A24: 2-F-008 | B24: ● 호스릴방식 노즐 개폐장치 사용 용이 여부
A25: 2-G. 전원
A26: 2-G-001 | B26: ● 대상물 수전방식에 따른 상용전원 적정 여부
A27: 2-G-002 | B27: ● 비상전원 설치장소 적정 및 관리 여부
A28: 2-G-003 | B28: ○ 자가발전설비인 경우 연료 적정량 보유 여부
A29: 2-G-004 | B29: ○ 자가발전설비인 경우「전기사업법」에 따른 정기점검 결과 확인
A30: 2-H. 제어반
A31: 2-H-001 | B31: ● 겸용 감시·동력 제어반 성능 적정 여부(겸용으로 설치된 경우)
B32: [감시제어반]
A33: 2-H-011 | B33: ○ 펌프 작동 여부 확인 표시등 및 음향경보장치 정상작동 여부
A34: 2-H-012 | B34: ○ 펌프 별 자동·수동 전환스위치 정상작동 여부
A35: 2-H-013 | B35: ● 펌프 별 수동기동 및 수동중단 기능 정상작동 여부
A36: 2-H-014 | B36: ● 상용전원 및 비상전원 공급 확인 가능 여부(비상전원 있는 경우)
A37: 2-H-015 | B37: ● 수조·물올림탱크 저수위 표시등 및 음향경보장치 정상작동 여부
A38: 2-H-016 | B38: ○ 각 확인회로 별 도통시험 및 작동시험 정상작동 여부
A39: 2-H-017 | B39: ○ 예비전원 확보 유무 및 시험 적합 여부

Sheet 옥3
A2: (3면)
A3: 번호 | C3: 점검항목 | J3: 점검결과
A4: 2-H-018 | C4: ● 감시제어반 전용실 적정 설치 및 관리 여부
A5: 2-H-019 | C5: ● 기계·기구 또는 시설 등 제어 및 감시설비 외 설치 여부 | O5: ○
C6: [동력제어반] | O6: /
A7: 2-H-021 | C7: ○ 앞면은 적색으로 하고,“옥내소화전설비용 동력제어반” 표지 설치 여부 | O7: ×
C8: [발전기제어반]
A9: 2-H-031 | C9: ● 소방전원보존형발전기는 이를 식별할 수 있는 표지 설치 여부
A10: * 펌프성능시험(펌프 명판 및 설계치 참조)
A11: 구분 | D11: 체절운전 | E11: 정격운전 (100%) | F11: 정격유량의 150%운전 | H11: 적 정 여 부 | J11: o 설정압력: o 주펌프 기동: MPa 정지: MPa o 예비펌프 기동: MPa 정지: MPa o 충압펌프 기동: MPa 정지: MPa
A12: 토출량 (ℓ/min) | C12: 주 | H12: 1. 체절운전시 토출압은 정격토출압의 140% 이하 ( ) 2. 정격운전시 토출량과 토출압이 규정치 이상( ) 3. 정격토출량 150%에서 토출압이 정격토출압의 65%이상 ( )
C13: 예비
A14: 토출압 (MPa) | C14: 주
C15: 예비
A16: * 릴리프밸브 작동 압력 : 1.60/1.70 MPa
A17: 비고

Sheet 스1
A1: 3. 스프링클러설비 점검표
A2: 번호 | B2: 점검항목 | C2: 점검결과
A3: 3-A. 수원
A4: 3-A-001 | B4: ○ 주된수원의 유효수량 적정 여부(겸용설비 포함)
A5: 3-A-002 | B5: ○ 보조수원(옥상)의 유효수량 적정 여부
A6: 3-B. 수조
A7: 3-B-001 | B7: ● 동결방지조치 상태 적정 여부 | G7: ○
A8: 3-B-002 | B8: ○ 수위계 설치 또는 수위 확인 가능 여부 | G8: /
A9: 3-B-003 | B9: ● 수조 외측 고정사다리 설치상태 적정 여부(바닥보다 낮은 경우 제외) | G9: ×
A10: 3-B-004 | B10: ● 실내설치 시 조명설비 설치 여부
A11: 3-B-005 | B11: ○“스프링클러설비용 수조”표지설치 여부 및 설치 상태
A12: 3-B-006 | B12: ● 다른 소화설비와 겸용 시 겸용설비의 이름 표시한 표지설치 여부
A13: 3-B-007 | B13: ● 수조-수직배관 접속부분“스프링클러설비용 배관”표지설치 여부
A14: 3-C. 가압송수장치
B15: [펌프방식]
A16: 3-C-001 | B16: ● 동결방지조치 상태 적정 여부
A17: 3-C-002 | B17: ○ 성능시험배관을 통한 펌프 성능시험 적정 여부
A18: 3-C-003 | B18: ● 다른 소화설비와 겸용인 경우 펌프 성능 확보 가능 여부
A19: 3-C-004 | B19: ○ 펌프 흡입측 연성계·진공계 및 토출측 압력계 등 부속장치의 변형·손상 유무
A20: 3-C-005 | B20: ● 기동장치 적정 설치 및 기동압력 설정 적정 여부
A21: 3-C-006 | B21: ● 물올림장치 설치 적정(전용 여부, 유효수량, 배관구경, 자동급수) 여부
A22: 3-C-007 | B22: ● 충압펌프 설치 적정(토출압력, 정격토출량) 여부
A23: 3-C-008 | B23: ○ 내연기관 방식의 펌프 설치 적정(정상기동(기동장치 및 제어반) 여부, 축전지상태, 연료량) 여부
A24: 3-C-009 | B24: ○ 가압송수장치의“스프링클러펌프”표지설치 여부 또는 다른 소화설비와 겸용 시 겸용설비 이름 표시 부착 여부
B25: [고가수조방식]
A26: 3-C-021 | B26: ○ 수위계·배수관·급수관·오버플로우관·맨홀 등 부속장치의 변형·손상 유무
B27: [압력수조방식]
A28: 3-C-031 | B28: ● 압력수조의 압력 적정 여부
A29: 3-C-032 | B29: ○ 수위계·급수관·급기관·압력계·안전장치·공기압축기 등 부속장치의 변형·손상 유무
B30: [가압수조방식]
A31: 3-C-041 | B31: ● 가압수조 및 가압원 설치장소의 방화구획 여부
A32: 3-C-042 | B32: ○ 수위계·급수관·배수관·급기관·압력계 등 부속장치의 변형·손상 유무
A33: 3-D. 폐쇄형스프링클러설비 방호구역 및 유수검지장치
A34: 3-D-001 | B34: ● 방호구역 적정 여부
A35: 3-D-002 | B35: ● 유수검지장치 설치 적정(수량, 접근·점검 편의성, 높이) 여부
A36: 3-D-003 | B36: ○ 유수검지장치실 설치 적정(실내 또는 구획, 출입문 크기, 표지) 여부

Sheet 스2
A1: (2면)
A2: 번호 | B2: 점검항목 | C2: 점검결과
A3: 3-D-004 | B3: ● 자연낙차에 의한 유수압력과 유수검지장치의 유수검지압력 적정여부
A4: 3-D-005 | B4: ● 조기반응형헤드 적합 유수검지장치 설치 여부
A5: 3-E. 개방형스프링클러설비 방수구역 및 일제개방밸브
A6: 3-E-001 | B6: ● 방수구역 적정 여부 | G6: ○
A7: 3-E-002 | B7: ● 방수구역 별 일제개방밸브 설치 여부 | G7: /
A8: 3-E-003 | B8: ● 하나의 방수구역을 담당하는 헤드 개수 적정 여부 | G8: ×
A9: 3-E-004 | B9: ○ 일제개방밸브실 설치 적정(실내(구획), 높이, 출입문, 표지) 여부
A10: 3-F. 배관
A11: 3-F-001 | B11: ● 펌프의 흡입측 배관 여과장치의 상태 확인
A12: 3-F-002 | B12: ● 성능시험배관 설치(개폐밸브, 유량조절밸브, 유량측정장치) 적정 여부
A13: 3-F-003 | B13: ● 순환배관 설치(설치위치·배관구경, 릴리프밸브 개방압력) 적정 여부
A14: 3-F-004 | B14: ● 동결방지조치 상태 적정 여부
A15: 3-F-005 | B15: ○ 급수배관 개폐밸브 설치(개폐표시형, 흡입측 버터플라이 제외) 및 작동표시 스위치 적정(제어반 표시 및 경보, 스위치 동작 및 도통시험) 여부
A16: 3-F-006 | B16: ○ 준비작동식 유수검지장치 및 일제개방밸브 2차측 배관 부대설비 설치 적정 (개폐표시형 밸브, 수직배수배관, 개폐밸브, 자동배수장치, 압력스위치 설치 및 감시제어반 개방 확인) 여부
A17: 3-F-007 | B17: ○ 유수검지장치 시험장치 설치 적정(설치위치, 배관구경, 개폐밸브 및 개방형 헤드, 물받이 통 및 배수관) 여부
A18: 3-F-008 | B18: ● 주차장에 설치된 스프링클러 방식 적정(습식 외의 방식) 여부
A19: 3-F-009 | B19: ● 다른 설비의 배관과의 구분 상태 적정 여부
A20: 3-G. 음향장치 및 기동장치
A21: 3-G-001 | B21: ○ 유수검지에 따른 음향장치 작동 가능 여부(습식·건식의 경우)
A22: 3-G-002 | B22: ○ 감지기 작동에 따라 음향장치 작동 여부(준비작동식 및 일제개방밸브의 경우)
A23: 3-G-003 | B23: ● 음향장치 설치 담당구역 및 수평거리 적정 여부
A24: 3-G-004 | B24: ● 주 음향장치 수신기 내부 또는 직근 설치 여부
A25: 3-G-005 | B25: ● 우선경보방식에 따른 경보 적정 여부
A26: 3-G-006 | B26: ○ 음향장치(경종 등) 변형·손상 확인 및 정상 작동(음량 포함) 여부
B27: [펌프 작동]
A28: 3-G-011 | B28: ○ 유수검지장치의 발신이나 기동용 수압개폐장치의 작동에 따른 펌프 기동 확인 (습식·건식의 경우)
A29: 3-G-012 | B29: ○ 화재감지기의 감지나 기동용 수압개폐장치의 작동에 따른 펌프 기동 확인 (준비작동식 및 일제개방밸브의 경우)
B30: [준비작동식유수검지장치 또는 일제개발밸브 작동]
A31: 3-G-021 | B31: ○ 담당구역내 화재감지기 동작(수동 기동 포함)에 따라 개방 및 작동 여부
A32: 3-G-022 | B32: ○ 수동조작함 (설치높이, 표시등) 설치 적정 여부

Sheet 스3
A1: (3면)
A2: 번호 | B2: 점검항목 | C2: 점검결과
A3: 3-H. 헤드
A4: 3-H-001 | B4: ○ 헤드의 변형·손상 유무
A5: 3-H-002 | B5: ○ 헤드 설치 위치·장소·상태(고정) 적정 여부
A6: 3-H-003 | B6: ○ 헤드 살수장애 여부
A7: 3-H-004 | B7: ● 무대부 또는 연소우려 있는 개구부 개방형 헤드 설치 여부
A8: 3-H-005 | B8: ● 조기반응형 헤드 설치 여부(의무 설치 장소의 경우)
A9: 3-H-006 | B9: ● 경사진 천장의 경우 스프링클러헤드의 배치상태 | G9: ○
A10: 3-H-007 | B10: ● 연소할 우려가 있는 개구부 헤드 설치 적정 여부 | G10: /
A11: 3-H-008 | B11: ● 습식·부압식스프링클러 외의 설비 상향식 헤드 설치 여부 | G11: ×
A12: 3-H-009 | B12: ● 측벽형 헤드 설치 적정 여부
A13: 3-H-010 | B13: ● 감열부에 영향을 받을 우려가 있는 헤드의 차폐판 설치 여부
A14: 3-I. 송수구
A15: 3-I-001 | B15: ○ 설치장소 적정 여부
A16: 3-I-002 | B16: ● 연결배관에 개폐밸브를 설치한 경우 개폐상태 확인 및 조작가능 여부
A17: 3-I-003 | B17: ● 송수구 설치 높이 및 구경 적정 여부
A18: 3-I-004 | B18: ○ 송수압력범위 표시 표지 설치 여부
A19: 3-I-005 | B19: ● 송수구 설치 개수 적정 여부(폐쇄형 스프링클러설비의 경우)
A20: 3-I-006 | B20: ● 자동배수밸브(또는 배수공)·체크밸브 설치 여부 및 설치 상태 적정 여부
A21: 3-I-007 | B21: ○ 송수구 마개 설치 여부
A22: 3-J. 전원
A23: 3-J-001 | B23: ● 대상물 수전방식에 따른 상용전원 적정 여부
A24: 3-J-002 | B24: ● 비상전원 설치장소 적정 및 관리 여부
A25: 3-J-003 | B25: ○ 자가발전설비인 경우 연료 적정량 보유 여부
A26: 3-J-004 | B26: ○ 자가발전설비인 경우「전기사업법」에 따른 정기점검 결과 확인
A27: 3-K. 제어반
A28: 3-K-001 | B28: ● 겸용 감시·동력 제어반 성능 적정 여부(겸용으로 설치된 경우)
B29: [감시제어반]
A30: 3-K-011 | B30: ○ 펌프 작동 여부 확인 표시등 및 음향경보장치 정상작동 여부
A31: 3-K-012 | B31: ○ 펌프 별 자동·수동 전환스위치 정상작동 여부
A32: 3-K-013 | B32: ● 펌프 별 수동기동 및 수동중단 기능 정상작동 여부
A33: 3-K-014 | B33: ● 상용전원 및 비상전원 공급 확인 가능 여부(비상전원 있는 경우)
A34: 3-K-015 | B34: ● 수조·물올림탱크 저수위 표시등 및 음향경보장치 정상작동 여부
A35: 3-K-016 | B35: ○ 각 확인회로 별 도통시험 및 작동시험 정상작동 여부
A36: 3-K-017 | B36: ○ 예비전원 확보 유무 및 시험 적합 여부
A37: 3-K-018 | B37: ● 감시제어반 전용실 적정 설치 및 관리 여부
A38: 3-K-019 | B38: ● 기계·기구 또는 시설 등 제어 및 감시설비 외 설치 여부
A39: 3-K-020 | B39: ○ 유수검지장치·일제개방밸브 작동 시 표시 및 경보 정상작동 여부
A40: 3-K-021 | B40: ○ 일제개방밸브 수동조작스위치 설치 여부

Sheet 스4
A2: (4면)
A3: 번호 | C3: 점검항목 | J3: 점검결과
A4: 3-K-022 | C4: ● 일제개방밸브 사용 설비 화재감지기 회로별 화재표시 적정 여부
A5: 3-K-023 | C5: ● 감시제어반과 수신기 간 상호 연동 여부(별도로 설치된 경우)
C6: [동력제어반] | O6: ○
A7: 3-K-031 | C7: ○ 앞면은 적색으로 하고, “스프링클러설비용 동력제어반” 표지 설치 여부 | O7: /
C8: [발전기제어반] | O8: ×
A9: 3-K-041 | C9: ● 소방전원보존형발전기는 이를 식별할 수 있는 표지 설치 여부
A10: 3-L. 헤드 설치제외
A11: 3-L-001 | C11: ● 헤드 설치 제외 적정 여부(설치 제외된 경우)
A12: 3-L-002 | C12: ● 드렌처설비 설치 적정 여부
A13: * 펌프성능시험(펌프 명판 및 설계치 참조)
A14: 구분 | D14: 체절운전 | E14: 정격운전 (100%) | F14: 정격유량의 150%운전 | H14: 적 정 여 부 | J14: o 설정압력: o 주펌프 기동: MPa 정지: MPa o 예비펌프 기동: MPa 정지: MPa o 충압펌프 기동: MPa 정지: MPa
A15: 토출량 (ℓ/min) | C15: 주 | H15: 1. 체절운전시 토출압은 정격토출압의 140% 이하 ( ) 2. 정격운전시 토출량과 토출압이 규정치 이상( ) 3. 정격토출량 150%에서 토출압이 정격토출압의 65%이상 ( )
C16: 예비
A17: 토출압 (MPa) | C17: 주
C18: 예비
A19: * 릴리프밸브 작동 압력 : 1.60/1.70 MPa
A20: 비고

Sheet 간1
A1: 4. 간이스프링클러설비 점검표
A2: 번호 | B2: 점검항목 | C2: 점검결과
A3: 4-A. 수원
A4: 4-A-001 | B4: ○ 수원의 유효수량 적정 여부(겸용설비 포함)
A5: 4-B. 수조
A6: 4-B-001 | B6: ○ 자동급수장치 설치 여부
A7: 4-B-002 | B7: ● 동결방지조치 상태 적정 여부
A8: 4-B-003 | B8: ○ 수위계 설치 또는 수위 확인 가능 여부 | G8: ○
A9: 4-B-004 | B9: ● 수조 외측 고정사다리 설치 여부(바닥보다 낮은 경우 제외) | G9: /
A10: 4-B-005 | B10: ● 실내설치 시 조명설비 설치 여부 | G10: ×
A11: 4-B-006 | B11: ○“간이스프링클러설비용 수조”표지 설치상태 적정 여부
A12: 4-B-007 | B12: ● 다른 소화설비와 겸용 시 겸용설비의 이름 표시한 표지설치 여부
A13: 4-B-008 | B13: ● 수조-수직배관 접속부분“간이스프링클러설비용 배관”표지설치 여부
A14: 4-C. 가압송수장치
B15: [상수도직결형]
A16: 4-C-001 | B16: ○ 방수량 및 방수압력 적정 여부
B17: [펌프방식]
A18: 4-C-011 | B18: ● 동결방지조치 상태 적정 여부
A19: 4-C-012 | B19: ○ 성능시험배관을 통한 펌프 성능시험 적정 여부
A20: 4-C-013 | B20: ● 다른 소화설비와 겸용인 경우 펌프 성능 확보 가능 여부
A21: 4-C-014 | B21: ○ 펌프 흡입측 연성계·진공계 및 토출측 압력계 등 부속장치의 변형·손상 유무
A22: 4-C-015 | B22: ● 기동장치 적정 설치 및 기동압력 설정 적정 여부
A23: 4-C-016 | B23: ● 물올림장치 설치 적정(전용 여부, 유효수량, 배관구경, 자동급수) 여부
A24: 4-C-017 | B24: ● 충압펌프 설치 적정(토출압력, 정격토출량) 여부
A25: 4-C-018 | B25: ○ 내연기관 방식의 펌프 설치 적정(정상기동(기동장치 및 제어반) 여부, 축전지상태, 연료량) 여부
A26: 4-C-019 | B26: ○ 가압송수장치의“간이스프링클러펌프”표지설치 여부 또는 다른 소화설비와 겸용 시 겸용설비 이름 표시 부착 여부
B27: [고가수조방식]
A28: 4-C-031 | B28: ○ 수위계·배수관·급수관·오버플로우관·맨홀 등 부속장치의 변형·손상 유무
B29: [압력수조방식]
A30: 4-C-041 | B30: ● 압력수조의 압력 적정 여부
A31: 4-C-042 | B31: ○ 수위계·급수관·급기관·압력계·안전장치·공기압축기 등 부속장치의 변형·손상 유무
B32: [가압수조방식]
A33: 4-C-051 | B33: ● 가압수조 및 가압원 설치장소의 방화구획 여부
A34: 4-C-052 | B34: ○ 수위계·급수관·배수관·급기관·압력계 등 부속장치의 변형·손상 유무
A35: 비고

Sheet 간2
A1: (2면)
A2: 번호 | B2: 점검항목 | C2: 점검결과
A3: 4-D. 방호구역 및 유수검지장치
A4: 4-D-001 | B4: ● 방호구역 적정 여부
A5: 4-D-002 | B5: ● 유수검지장치 설치 적정(수량, 접근·점검 편의성, 높이) 여부
A6: 4-D-003 | B6: ○ 유수검지장치실 설치 적정(실내 또는 구획, 출입문 크기, 표지) 여부
A7: 4-D-004 | B7: ● 자연낙차에 의한 유수압력과 유수검지장치의 유수검지압력 적정여부 | F7: ○
A8: 4-D-005 | B8: ● 주차장에 설치된 간이스프링클러 방식 적정(습식 외의 방식) 여부 | F8: /
A9: 4-E. 배관 및 밸브 | F9: ×
A10: 4-E-001 | B10: ○ 상수도직결형 수도배관 구경 및 유수검지에 따른 다른 배관 자동 송수 차단 여부
A11: 4-E-002 | B11: ○ 급수배관 개폐밸브 설치(개폐표시형, 흡입측 버터플라이 제외) 및 작동표시 스위치 적정(제어반 표시 및 경보, 스위치 동작 및 도통시험) 여부
A12: 4-E-003 | B12: ● 펌프의 흡입측 배관 여과장치의 상태 확인
A13: 4-E-004 | B13: ● 성능시험배관 설치(개폐밸브, 유량조절밸브, 유량측정장치) 적정 여부
A14: 4-E-005 | B14: ● 순환배관 설치(설치위치·배관구경, 릴리프밸브 개방압력) 적정 여부
A15: 4-E-006 | B15: ● 동결방지조치 상태 적정 여부
A16: 4-E-007 | B16: ○ 준비작동식 유수검지장치 2차측 배관 부대설비 설치 적정(개폐표시형 밸브, 수직배수 배관·개폐밸브, 자동배수장치, 압력스위치 설치 및 감시제어반 개방 확인) 여부
A17: 4-E-008 | B17: ○ 유수검지장치 시험장치 설치 적정(설치위치, 배관구경, 개폐밸브 및 개방형 헤드, 물받이 통 및 배수관) 여부
A18: 4-E-009 | B18: ● 간이스프링클러설비 배관 및 밸브 등의 순서의 적정 시공 여부
A19: 4-E-010 | B19: ● 다른 설비의 배관과의 구분 상태 적정 여부
A20: 4-F. 음향장치 및 기동장치
A21: 4-F-001 | B21: ○ 유수검지에 따른 음향장치 작동 가능 여부(습식의 경우)
A22: 4-F-002 | B22: ● 음향장치 설치 담당구역 및 수평거리 적정 여부
A23: 4-F-003 | B23: ● 주 음향장치 수신기 내부 또는 직근 설치 여부
A24: 4-F-004 | B24: ● 우선경보방식에 따른 경보 적정 여부
A25: 4-F-005 | B25: ○ 음향장치(경종 등) 변형·손상 확인 및 정상 작동(음량 포함) 여부
B26: [펌프 작동]
A27: 4-F-011 | B27: ○ 유수검지장치의 발신이나 기동용 수압개폐장치의 작동에 따른 펌프 기동 확인 (습식의 경우)
A28: 4-F-012 | B28: ○ 화재감지기의 감지나 기동용 수압개폐장치의 작동에 따른 펌프 기동 확인 (준비작동식의 경우)
B29: [준비작동식유수검지장치 작동]
A30: 4-F-021 | B30: ○ 담당구역내 화재감지기 동작(수동 기동 포함)에 따라 개방 및 작동 여부
A31: 4-F-022 | B31: ○ 수동조작함 (설치높이, 표시등) 설치 적정 여부
A32: 비고

Sheet 간3
A1: (3면)
A2: 번호 | B2: 점검항목 | C2: 점검결과
A3: 4-G. 간이헤드
A4: 4-G-001 | B4: ○ 헤드의 변형·손상 유무
A5: 4-G-002 | B5: ○ 헤드 설치 위치·장소·상태(고정) 적정 여부
A6: 4-G-003 | B6: ○ 헤드 살수장애 여부
A7: 4-G-004 | B7: ● 감열부에 영향을 받을 우려가 있는 헤드의 차폐판 설치 여부
A8: 4-G-005 | B8: ● 헤드 설치 제외 적정 여부(설치 제외된 경우)
A9: 4-H. 송수구 | G9: ○
A10: 4-H-001 | B10: ○ 설치장소 적정 여부 | G10: /
A11: 4-H-002 | B11: ● 연결배관에 개폐밸브를 설치한 경우 개폐상태 확인 및 조작가능 여부 | G11: ×
A12: 4-H-003 | B12: ● 송수구 설치 높이 및 구경 적정 여부
A13: 4-H-004 | B13: ● 자동배수밸브(또는 배수공)·체크밸브 설치 여부 및 설치 상태 적정 여부
A14: 4-H-005 | B14: ○ 송수구 마개 설치 여부
A15: 4-I. 제어반
A16: 4-I-001 | B16: ● 겸용 감시·동력 제어반 성능 적정 여부(겸용으로 설치된 경우)
B17: [감시제어반]
A18: 4-I-011 | B18: ○ 펌프 작동 여부 확인 표시등 및 음향경보장치 정상작동 여부
A19: 4-I-012 | B19: ○ 펌프 별 자동·수동 전환스위치 정상작동 여부
A20: 4-I-013 | B20: ● 펌프 별 수동기동 및 수동중단 기능 정상작동 여부
A21: 4-I-014 | B21: ● 상용전원 및 비상전원 공급 확인 가능 여부(비상전원 있는 경우)
A22: 4-I-015 | B22: ● 수조·물올림탱크 저수위 표시등 및 음향경보장치 정상작동 여부
A23: 4-I-016 | B23: ○ 각 확인회로 별 도통시험 및 작동시험 정상작동 여부
A24: 4-I-017 | B24: ○ 예비전원 확보 유무 및 시험 적합 여부
A25: 4-I-018 | B25: ● 감시제어반 전용실 적정 설치 및 관리 여부
A26: 4-I-019 | B26: ● 기계·기구 또는 시설 등 제어 및 감시설비 외 설치 여부
A27: 4-I-020 | B27: ○ 유수검지장치 작동 시 표시 및 경보 정상작동 여부
A28: 4-I-021 | B28: ● 감시제어반과 수신기 간 상호 연동 여부(별도로 설치된 경우)
B29: [동력제어반]
A30: 4-I-031 | B30: ○ 앞면은 적색으로 하고,“간이스프링클러설비용 동력제어반”표지 설치 여부
B31: [발전기제어반]
A32: 4-I-041 | B32: ● 소방전원보존형발전기는 이를 식별할 수 있는 표지 설치 여부
A33: 4-J. 전원
A34: 4-J-001 | B34: ● 대상물 수전방식에 따른 상용전원 적정 여부
A35: 4-J-002 | B35: ● 비상전원 설치장소 적정 및 관리 여부
A36: 4-J-003 | B36: ○ 자가발전설비인 경우 연료 적정량 보유 여부
A37: 4-J-004 | B37: ○ 자가발전설비인 경우「전기사업법」에 따른 정기점검 결과 확인
A38: 비고

Sheet 간4
A2: (4면)
A3: 번호 | C3: 점검항목 | J3: 점검결과
A4: * 펌프성능시험(펌프 명판 및 설계치 참조)
A5: 구분 | D5: 체절운전 | E5: 정격운전 (100%) | F5: 정격유량의 150%운전 | H5: 적 정 여 부 | J5: o 설정압력: o 주펌프 기동: MPa 정지: MPa o 예비펌프 기동: MPa 정지: MPa o 충압펌프 기동: MPa 정지: MPa
A6: 토출량 (ℓ/min) | C6: 주 | H6: 1. 체절운전시 토출압은 정격토출압의 140% 이하 ( ) 2. 정격운전시 토출량과 토출압이 규정치 이상( ) 3. 정격토출량 150%에서 토출압이 정격토출압의 65%이상 ( )
C7: 예비
A8: 토출압 (MPa) | C8: 주
C9: 예비
A10: * 릴리프밸브 작동 압력 : 1.60/1.70 MPa
A11: 비고

Sheet CO2-1
A1: 9. 이산화탄소소화설비 점검표
A2: 번호 | B2: 점검항목 | C2: 점검결과
A3: 9-A. 저장용기
A4: 9-A-001 | B4: ● 설치장소 적정 및 관리 여부
A5: 9-A-002 | B5: ○ 저장용기 설치장소 표지 설치 여부
A6: 9-A-003 | B6: ● 저장용기 설치 간격 적정 여부 | G6: ○
A7: 9-A-004 | B7: ○ 저장용기 개방밸브 자동·수동 개방 및 안전장치 부착 여부 | G7: /
A8: 9-A-005 | B8: ● 저장용기와 집합관 연결배관 상 체크밸브 설치 여부 | G8: ×
A9: 9-A-006 | B9: ● 저장용기와 선택밸브(또는 개폐밸브) 사이 안전장치 설치 여부
B10: [저압식]
A11: 9-A-011 | B11: ● 안전밸브 및 봉판 설치 적정(작동 압력) 여부
A12: 9-A-012 | B12: ● 액면계․압력계 설치 여부 및 압력강하경보장치 작동 압력 적정 여부
A13: 9-A-013 | B13: ○ 자동냉동장치의 기능
A14: 9-B. 소화약제
A15: 9-B-001 | B15: ○ 소화약제 저장량 적정 여부
A16: 9-C. 기동장치
A17: 9-C-001 | B17: ○ 방호구역별 출입구 부근 소화약제 방출표시등 설치 및 정상 작동 여부
B18: [수동식 기동장치]
A19: 9-C-011 | B19: ○ 기동장치 부근에 비상스위치 설치 여부
A20: 9-C-012 | B20: ● 방호구역별 또는 방호대상별 기동장치 설치 여부
A21: 9-C-013 | B21: ○ 기동장치 설치 적정(출입구 부근 등, 높이, 보호장치, 표지, 전원표시등) 여부
A22: 9-C-014 | B22: ○ 방출용 스위치 음향경보장치 연동 여부
B23: [자동식 기동장치]
A24: 9-C-021 | B24: ○ 감지기 작동과의 연동 및 수동기동 가능 여부
A25: 9-C-022 | B25: ● 저장용기 수량에 따른 전자 개방밸브 수량 적정 여부(전기식 기동장치의 경우)
A26: 9-C-023 | B26: ○ 기동용 가스용기의 용적, 충전압력 적정 여부(가스압력식 기동장치의 경우)
